Workbook

Sheet 요약
A1: 부캉이 낚시터 밸런스 요약
A2: 숫자는 다른 시트와 연결돼 있어 가정·물고기·장비 시트 값을 바꾸면 함께 바뀝니다.
A4: 항목 | B4: 값 | C4: 메모
A5: 실내 낚시터 1마리 기대 판매가 (원) | B5: =낚시터!F5 -> 15.956293 | C5: 떡밥·방식 무관 기준
A6: 하천 1마리 기대 판매가 (원) | B6: =낚시터!F6 -> 22.906001 | C6: 떡밥·방식 무관 기준
A7: 강 1마리 기대 판매가 (원) | B7: =낚시터!F7 -> 47.014867 | C7: 떡밥·방식 무관 기준
A8: 방파제 1마리 기대 판매가 (원) | B8: =낚시터!F8 -> 122.22154 | C8: 떡밥·방식 무관 기준
A9: 독도 1마리 기대 판매가 (원) | B9: =낚시터!F9 -> 269.42919 | C9: 떡밥·방식 무관 기준
A10: 배낚시 1마리 기대 판매가 (원) | B10: =낚시터!F10 -> 758.26928 | C10: 떡밥·방식 무관 기준
A11: 아마존 1마리 기대 판매가 (원) | B11: =낚시터!F11 -> 1261.8303 | C11: 떡밥·방식 무관 기준
A12: 알래스카 1마리 기대 판매가 (원) | B12: =낚시터!F12 -> 2008.837 | C12: 떡밥·방식 무관 기준
A13: 부산 1마리 기대 판매가 (원) | B13: =낚시터!F13 -> 1944.8077 | C13: 떡밥·방식 무관 기준
A14: 실내 낚시터 → 하천 해금까지 기대 마릿수 | B14: =낚시터!G5 -> 0 | C14: 장비 강화에 돈을 안 쓴다고 가정
A15: 하천 → 강 해금까지 기대 마릿수 | B15: =낚시터!G6 -> 27 | C15: 장비 강화에 돈을 안 쓴다고 가정
A16: 강 → 방파제 해금까지 기대 마릿수 | B16: =낚시터!G7 -> 32 | C16: 장비 강화에 돈을 안 쓴다고 가정
A17: 방파제 → 독도 해금까지 기대 마릿수 | B17: =낚시터!G8 -> 25 | C17: 장비 강화에 돈을 안 쓴다고 가정
A18: 독도 → 배낚시 해금까지 기대 마릿수 | B18: =낚시터!G9 -> 30 | C18: 장비 강화에 돈을 안 쓴다고 가정
A19: 배낚시 → 아마존 해금까지 기대 마릿수 | B19: =낚시터!G10 -> 33 | C19: 장비 강화에 돈을 안 쓴다고 가정
A20: 아마존 → 알래스카 해금까지 기대 마릿수 | B20: =낚시터!G11 -> 40 | C20: 장비 강화에 돈을 안 쓴다고 가정
A21: 장비 4종 10단계까지 총비용 (원) | B21: =장비!D45 -> 9449700
A22: 알래스카로 총비용을 벌려면 기대 마릿수 | B22: =ROUNDUP(B21/낚시터!F12,0) -> 4705 | C22: 알래스카 기대 판매가 기준
A23: 부캉이까지 기대 입질 수 (떡밥) | B23: =장비!I35 -> 250
A24: 부캉이까지 기대 입질 수 (황금 미끼) | B24: =장비!I39 -> 96
A25: 부캉이까지 기대 입질 수 (황금 미끼 +5) | B25: =장비!I44 -> 69
A26: 알래스카 기대 판매가: 가장 가까이 (원) | B26: =낚시터!I12 -> 1884.1082 | C26: 캐스팅 게이지 0
A27: 알래스카 기대 판매가: 가장 멀리 (원) | B27: =낚시터!J12 -> 2158.4153 | C27: 캐스팅 게이지 끝
A28: 그물 전체 강화 비용 (원) | B28: =그물!D10 -> 535000 | C28: 작은 그물 ~ 황금 그물
A29: 작은 그물 배낚시 분당 수입 (원) | B29: =그물!O6 -> 446.02522
A30: 황금 그물 배낚시 분당 수입 (원) | B30: =그물!O10 -> 2568.327
A31: 황금 그물 알래스카 분당 수입 (원) | B31: =그물!P10 -> 4970.8729
A32: 부산 이용권 1장 시간 (초) | B32: =가정!$B$11 -> 150 | C32: 부산 도감 완성 시 +30초
A33: 살림망 칸 수 | B33: =가정!$B$4 -> 15 | C33: 자동 판매가 생겨 도감 보상에서 뺌
A34: 기본 대 적정 구간 (가장 쉬운 붕어) | B34: =물고기!R5 -> 0.24495 | C34: 장력 0~1 중 초록 구간 폭
A35: 기본 대 적정 구간 (오륙도 돗돔) | B35: =물고기!R51 -> 0.138
A36: 최고 대 적정 구간 (오륙도 돗돔) | B36: =물고기!S51 -> 0.23575

Sheet 가정
A1: 가정 (값을 바꾸면 모든 시트가 다시 계산됩니다)
A2: 파란 글자·노란 칸이 입력값입니다. 게임 값은 index.html 맨 위 CONFIG에 있고, 이 표를 바꿔도 게임은 바뀌지 않습니다.
A3: 항목 | B3: 값 | C3: 출처 / 설명
A4: 살림망 칸 수 | B4: 15 | C4: CONFIG.keepNetSize
A5: 크기 분포 지수 (떡밥) | B5: 1.8 | C5: rollCatch: t = 난수^지수, 길이 = 최소 + (최대−최소)×t. 지수가 클수록 작은 개체가 흔함
A6: 크기 지수 행운 감소 | B6: 0.6 | C6: 지수 = max(0.9, 1.8 − 미끼 행운×0.6)
A7: 희귀 가중치 행운 계수 | B7: 0.35 | C7: 출현 가중치 × (1 + 행운×등급번호×0.35)
A8: 선호 방식 출현 배수 | B8: 1.5 | C8: CONFIG.methodSpawnBonus — 지금 방식을 좋아하는 물고기가 더 자주 나옴
A9: 부캉이 기본 확률 (입질 1회당) | B9: 0.004 | C9: CONFIG.bukangi.baseChance
A10: 부캉이 행운 배수 | B10: 2 | C10: 확률 = 기본 × (1 + 미끼 행운×배수)
A11: 부산 이용권 1장 시간 (초) | B11: 150 | C11: CONFIG.busan.ticketSeconds
A12: 튜토리얼 보상 (원) | B12: 150 | C12: CONFIG.tutorial.reward
A13: 거리 1.0 = 몇 m | B13: 30 | C13: CONFIG.maxMeters (화면 표시용)
A14: 난이도 1일 때 장력 구간 축소 | B14: 0.5 | C14: CONFIG.reel.zoneShrinkByDiff
A15: 선호 방식 장력 구간 배수 | B15: 1.15 | C15: CONFIG.methodMatch.zoneMul
... A32: 멀리 던졌을 때 시작 거리 배수 | B32: 1.15 | C32: CONFIG.cast.startDistFar — 도망 거리(1.3)에 더 가까워 위험↑

Sheet 등급
A1: 등급 기준
A2: 판매 가격이 최소 가격 이상이면 해당 등급입니다. 같은 종이라도 크기에 따라 등급이 달라집니다.
A3: 등급 | B3: 최소 가격 (원) | C3: 표시 색 | D3: 최대 크기 기준 종 수
A4: 일반 | B4: 0 | C4: #a9b4ba | D4: =COUNTIF(물고기!$O$5:$O$200,A4) -> 7
A5: 고급 | B5: 60 | C5: #5cc27a | D5: =COUNTIF(물고기!$O$5:$O$200,A5) -> 5
A6: 희귀 | B6: 200 | C6: #4aa3ff | D6: =COUNTIF(물고기!$O$5:$O$200,A6) -> 7
A7: 영웅 | B7: 700 | C7: #b678ff | D7: =COUNTIF(물고기!$O$5:$O$200,A7) -> 8
A8: 전설 | B8: 2500 | C8: #ffb627 | D8: =COUNTIF(물고기!$O$5:$O$200,A8) -> 20
A9: 특별 | B9: 부캉이 전용 | C9: #ff7eb6

Sheet 장비
A1: 장비 강화
A2: 레벨 1은 처음부터 가진 장비입니다. 비용은 그 레벨로 올릴 때 드는 금액입니다.
A4: 장비 | B4: 레벨 | C4: 이름 | D4: 강화 비용 (원) | E4: 누적 비용 (원) | F4: 수치 | G4: 수치 뜻 | H4: 부캉이 확률 (입질 1회당) | I4: 부캉이까지 기대 입질 수
A5: 낚싯대 | B5: 1 | C5: 일반 낚싯대 | D5: 0 | E5: =SUM($D$5:D5) -> 0 | F5: 0.24 | G5: 적정 장력 구간 폭 (대를 세우면 돌진 흡수 30%)
A6: 낚싯대 | B6: 2 | C6: 카본 낚싯대 | D6: 200 | E6: =SUM($D$5:D6) -> 200 | F6: 0.28 | G6: 적정 장력 구간 폭 (대를 세우면 돌진 흡수 38%)
A7: 낚싯대 | B7: 3 | C7: 강화 카본대 | D7: 1200 | E7: =SUM($D$5:D7) -> 1400 | F7: 0.32 | G7: 적정 장력 구간 폭 (대를 세우면 돌진 흡수 45%)
A8: 낚싯대 | B8: 4 | C8: 마스터 로드 | D8: 6000 | E8: =SUM($D$5:D8) -> 7400 | F8: 0.36 | G8: 적정 장력 구간 폭 (대를 세우면 돌진 흡수 52%)
A9: 낚싯대 | B9: 5 | C9: 전설의 장대 | D9: 25000 | E9: =SUM($D$5:D9) -> 32400 | F9: 0.41 | G9: 적정 장력 구간 폭 (대를 세우면 돌진 흡수 60%)
A10: 낚싯대 | B10: 6 | C10: 전설의 장대 +1 | D10: 60000 | E10: =SUM($D$5:D10) -> 92400 | F10: 0.43 | G10: 적정 장력 구간 폭 (대를 세우면 돌진 흡수 62%)
A11: 낚싯대 | B11: 7 | C11: 전설의 장대 +2 | D11: 130000 | E11: =SUM($D$5:D11) -> 222400 | F11: 0.45 | G11: 적정 장력 구간 폭 (대를 세우면 돌진 흡수 64%)
A12: 낚싯대 | B12: 8 | C12: 전설의 장대 +3 | D12: 280000 | E12: =SUM($D$5:D12) -> 502400 | F12: 0.47 | G12: 적정 장력 구간 폭 (대를 세우면 돌진 흡수 66%)
A13: 낚싯대 | B13: 9 | C13: 전설의 장대 +4 | D13: 600000 | E13: =SUM($D$5:D13) -> 1102400 | F13: 0.49 | G13: 적정 장력 구간 폭 (대를 세우면 돌진 흡수 68%)
A14: 낚싯대 | B14: 10 | C14: 전설의 장대 +5 | D14: 1300000 | E14: =SUM($D$5:D14) -> 2402400 | F14: 0.51 | G14: 적정 장력 구간 폭 (대를 세우면 돌진 흡수 70%)
A15: 릴 | B15: 1 | C15: 기본 스피닝릴 | D15: 0 | E15: =SUM($D$15:D15) -> 0 | F15: 0.16 | G15: 감기 속도 (거리/초)
A16: 릴 | B16: 2 | C16: 정밀 스피닝릴 | D16: 250 | E16: =SUM($D$15:D16) -> 250 | F16: 0.21 | G16: 감기 속도 (거리/초)
A17: 릴 | B17: 3 | C17: 하이기어 릴 | D17: 1500 | E17: =SUM($D$15:D17) -> 1750 | F17: 0.27 | G17: 감기 속도 (거리/초)
A18: 릴 | B18: 4 | C18: 전동 릴 | D18: 7000 | E18: =SUM($D$15:D18) -> 8750 | F18: 0.34 | G18: 감기 속도 (거리/초)
A19: 릴 | B19: 5 | C19: 명인의 릴 | D19: 30000 | E19: =SUM($D$15:D19) -> 38750 | F19: 0.42 | G19: 감기 속도 (거리/초)
A20: 릴 | B20: 6 | C20: 명인의 릴 +1 | D20: 70000 | E20: =SUM($D$15:D20) -> 108750 | F20: 0.45 | G20: 감기 속도 (거리/초)
A21: 릴 | B21: 7 | C21: 명인의 릴 +2 | D21: 150000 | E21: =SUM($D$15:D21) -> 258750 | F21: 0.48 | G21: 감기 속도 (거리/초)
A22: 릴 | B22: 8 | C22: 명인의 릴 +3 | D22: 320000 | E22: =SUM($D$15:D22) -> 578750 | F22: 0.51 | G22: 감기 속도 (거리/초)
A23: 릴 | B23: 9 | C23: 명인의 릴 +4 | D23: 700000 | E23: =SUM($D$15:D23) -> 1278750 | F23: 0.54 | G23: 감기 속도 (거리/초)
A24: 릴 | B24: 10 | C24: 명인의 릴 +5 | D24: 1500000 | E24: =SUM($D$15:D24) -> 2778750 | F24: 0.57 | G24: 감기 속도 (거리/초)
A25: 낚싯줄 | B25: 1 | C25: 나일론 2호 | D25: 0 | E25: =SUM($D$25:D25) -> 0 | F25: 1.2 | G25: 장력 초과를 버티는 시간 (초)
A26: 낚싯줄 | B26: 2 | C26: 나일론 4호 | D26: 150 | E26: =SUM($D$25:D26) -> 150 | F26: 1.7 | G26: 장력 초과를 버티는 시간 (초)
A27: 낚싯줄 | B27: 3 | C27: 카본 5호 | D27: 1000 | E27: =SUM($D$25:D27) -> 1150 | F27: 2.4 | G27: 장력 초과를 버티는 시간 (초)
A28: 낚싯줄 | B28: 4 | C28: PE 3호 | D28: 5000 | E28: =SUM($D$25:D28) -> 6150 | F28: 3.3 | G28: 장력 초과를 버티는 시간 (초)
A29: 낚싯줄 | B29: 5 | C29: 초강력 PE | D29: 22000 | E29: =SUM($D$25:D29) -> 28150 | F29: 4.5 | G29: 장력 초과를 버티는 시간 (초)
A30: 낚싯줄 | B30: 6 | C30: 초강력 PE +1 | D30: 50000 | E30: =SUM($D$25:D30) -> 78150 | F30: 5 | G30: 장력 초과를 버티는 시간 (초)
A31: 낚싯줄 | B31: 7 | C31: 초강력 PE +2 | D31: 110000 | E31: =SUM($D$25:D31) -> 188150 | F31: 5.5 | G31: 장력 초과를 버티는 시간 (초)
A32: 낚싯줄 | B32: 8 | C32: 초강력 PE +3 | D32: 240000 | E32: =SUM($D$25:D32) -> 428150 | F32: 6 | G32: 장력 초과를 버티는 시간 (초)
A33: 낚싯줄 | B33: 9 | C33: 초강력 PE +4 | D33: 520000 | E33: =SUM($D$25:D33) -> 948150 | F33: 6.5 | G33: 장력 초과를 버티는 시간 (초)
A34: 낚싯줄 | B34: 10 | C34: 초강력 PE +5 | D34: 1100000 | E34: =SUM($D$25:D34) -> 2048150 | F34: 7 | G34: 장력 초과를 버티는 시간 (초)
A35: 미끼 | B35: 1 | C35: 떡밥 | D35: 0 | E35: =SUM($D$35:D35) -> 0 | F35: 0 | G35: 미끼 행운 (희귀 출현·큰 개체·부캉이) | H35: =가정!$B$9*(1+F35*가정!$B$10) -> 0.004 | I35: =ROUND(1/H35,0) -> 250
A36: 미끼 | B36: 2 | C36: 지렁이 | D36: 100 | E36: =SUM($D$35:D36) -> 100 | F36: 0.15 | G36: 미끼 행운 (희귀 출현·큰 개체·부캉이) | H36: =가정!$B$9*(1+F36*가정!$B$10) -> 0.0052 | I36: =ROUND(1/H36,0) -> 192
A37: 미끼 | B37: 3 | C37: 크릴 | D37: 800 | E37: =SUM($D$35:D37) -> 900 | F37: 0.3 | G37: 미끼 행운 (희귀 출현·큰 개체·부캉이) | H37: =가정!$B$9*(1+F37*가정!$B$10) -> 0.0064 | I37: =ROUND(1/H37,0) -> 156
A38: 미끼 | B38: 4 | C38: 생미끼 | D38: 4500 | E38: =SUM($D$35:D38) -> 5400 | F38: 0.5 | G38: 미끼 행운 (희귀 출현·큰 개체·부캉이) | H38: =가정!$B$9*(1+F38*가정!$B$10) -> 0.008 | I38: =ROUND(1/H38,0) -> 125
A39: 미끼 | B39: 5 | C39: 황금 미끼 | D39: 20000 | E39: =SUM($D$35:D39) -> 25400 | F39: 0.8 | G39: 미끼 행운 (희귀 출현·큰 개체·부캉이) | H39: =가정!$B$9*(1+F39*가정!$B$10) -> 0.0104 | I39: =ROUND(1/H39,0) -> 96
A40: 미끼 | B40: 6 | C40: 황금 미끼 +1 | D40: 55000 | E40: =SUM($D$35:D40) -> 80400 | F40: 0.9 | G40: 미끼 행운 (희귀 출현·큰 개체·부캉이) | H40: =가정!$B$9*(1+F40*가정!$B$10) -> 0.0112 | I40: =ROUND(1/H40,0) -> 89
A41: 미끼 | B41: 7 | C41: 황금 미끼 +2 | D41: 120000 | E41: =SUM($D$35:D41) -> 200400 | F41: 1 | G41: 미끼 행운 (희귀 출현·큰 개체·부캉이) | H41: =가정!$B$9*(1+F41*가정!$B$10) -> 0.012 | I41: =ROUND(1/H41,0) -> 83
...

Sheet 물고기
A1: 물고기 표
A2: 가격은 평균 길이 기준가 × (길이 ÷ 평균 길이)². 기대 판매가는 떡밥(행운 0) 기준 크기 분포로 계산합니다.
A4: ID | B4: 이름 | C4: 선호 방식 | D4: 부산 전용 | E4: 최소 길이 (cm) | F4: 최대 길이 (cm) | G4: 기준가 (원) | H4: 저항 (0~1) | I4: 평균 길이 (cm) | J4: 최소 크기 가격 (원) | K4: 최대 크기 가격 (원) | L4: 1마리 기대 판매가 (원) | M4: 최소 등급 | N4: 등급 번호 (최대) | O4: 최대 등급 | P4: 난이도 최소 | Q4: 난이도 최대 | R4: 적정 구간 기본 대·최대 난이도 | S4: 적정 구간 최고 대·최대 난이도 | T4: 기준가 등급 번호 (출현 가중)
A5: bungeo | B5: 붕어 | C5: 찌낚시 | E5: 12 | F5: 30 | G5: 12 | H5: 0.15 | I5: =(E5+F5)/2 -> 21 | J5: =MAX(1,ROUND(G5*(E5/I5)^2,0)) -> 4 | K5: =MAX(1,ROUND(G5*(F5/I5)^2,0)) -> 24 | L5: =G5*(E5^2+2*E5*(F5-E5)/(1+가정!$B$5)+(F5-E5)^2/(1+2*가정!$B$5))/I5^2 -> 10.033211 | M5: =INDEX(등급!$A$4:$A$8,MATCH(J5,등급!$B$4:$B$8,1)) -> 일반 | N5: =MATCH(K5,등급!$B$4:$B$8,1)-1 -> 0 | O5: =INDEX(등급!$A$4:$A$8,N5+1) -> 일반 | P5: =MIN(1,H5*가정!$B$24+(MATCH(J5,등급!$B$4:$B$8,1)-1)*가정!$B$25) -> 0.105 | Q5: =MIN(1,H5*가정!$B$24+N5*가정!$B$25+가정!$B$26) -> 0.225 | R5: =장비!$F$5*(1-Q5*가정!$B$14)*가정!$B$15 -> 0.24495 | S5: =장비!$F$9*(1-Q5*가정!$B$14)*가정!$B$15 -> 0.41845625 | T5: =MATCH(G5,등급!$B$4:$B$8,1)-1 -> 0
A6: hyangeo | B6: 향어 | C6: 찌낚시 | E6: 25 | F6: 50 | G6: 30 | H6: 0.3 | I6: =(E6+F6)/2 -> 37.5 | J6: =MAX(1,ROUND(G6*(E6/I6)^2,0)) -> 13 | K6: =MAX(1,ROUND(G6*(F6/I6)^2,0)) -> 53 | L6: =G6*(E6^2+2*E6*(F6-E6)/(1+가정!$B$5)+(F6-E6)^2/(1+2*가정!$B$5))/I6^2 -> 25.755694 | M6: =INDEX(등급!$A$4:$A$8,MATCH(J6,등급!$B$4:$B$8,1)) -> 일반 | N6: =MATCH(K6,등급!$B$4:$B$8,1)-1 -> 0 | O6: =INDEX(등급!$A$4:$A$8,N6+1) -> 일반 | P6: =MIN(1,H6*가정!$B$24+(MATCH(J6,등급!$B$4:$B$8,1)-1)*가정!$B$25) -> 0.21 | Q6: =MIN(1,H6*가정!$B$24+N6*가정!$B$25+가정!$B$26) -> 0.33 | R6: =장비!$F$5*(1-Q6*가정!$B$14)*가정!$B$15 -> 0.23046 | S6: =장비!$F$9*(1-Q6*가정!$B$14)*가정!$B$15 -> 0.3937025 | T6: =MATCH(G6,등급!$B$4:$B$8,1)-1 -> 0
A7: ingeo | B7: 잉어 | C7: 찌낚시 | E7: 30 | F7: 80 | G7: 60 | H7: 0.45 | I7: =(E7+F7)/2 -> 55 | J7: =MAX(1,ROUND(G7*(E7/I7)^2,0)) -> 18 | K7: =MAX(1,ROUND(G7*(F7/I7)^2,0)) -> 127 | L7: =G7*(E7^2+2*E7*(F7-E7)/(1+가정!$B$5)+(F7-E7)^2/(1+2*가정!$B$5))/I7^2 -> 49.88245 | M7: =INDEX(등급!$A$4:$A$8,MATCH(J7,등급!$B$4:$B$8,1)) -> 일반 | N7: =MATCH(K7,등급!$B$4:$B$8,1)-1 -> 1 | O7: =INDEX(등급!$A$4:$A$8,N7+1) -> 고급 | P7: =MIN(1,H7*가정!$B$24+(MATCH(J7,등급!$B$4:$B$8,1)-1)*가정!$B$25) -> 0.315 | Q7: =MIN(1,H7*가정!$B$24+N7*가정!$B$25+가정!$B$26) -> 0.485 | R7: =장비!$F$5*(1-Q7*가정!$B$14)*가정!$B$15 -> 0.20907 | S7: =장비!$F$9*(1-Q7*가정!$B$14)*가정!$B$15 -> 0.35716125 | T7: =MATCH(G7,등급!$B$4:$B$8,1)-1 -> 1
A8: pirami | B8: 피라미 | C8: 찌낚시 | E8: 6 | F8: 15 | G8: 6 | H8: 0.1 | I8: =(E8+F8)/2 -> 10.5 | J8: =MAX(1,ROUND(G8*(E8/I8)^2,0)) -> 2 | K8: =MAX(1,ROUND(G8*(F8/I8)^2,0)) -> 12 | L8: =G8*(E8^2+2*E8*(F8-E8)/(1+가정!$B$5)+(F8-E8)^2/(1+2*가정!$B$5))/I8^2 -> 5.0166054 | M8: =INDEX(등급!$A$4:$A$8,MATCH(J8,등급!$B$4:$B$8,1)) -> 일반 | N8: =MATCH(K8,등급!$B$4:$B$8,1)-1 -> 0 | O8: =INDEX(등급!$A$4:$A$8,N8+1) -> 일반 | P8: =MIN(1,H8*가정!$B$24+(MATCH(J8,등급!$B$4:$B$8,1)-1)*가정!$B$25) -> 0.07 | Q8: =MIN(1,H8*가정!$B$24+N8*가정!$B$25+가정!$B$26) -> 0.19 | R8: =장비!$F$5*(1-Q8*가정!$B$14)*가정!$B$15 -> 0.24978 | S8: =장비!$F$9*(1-Q8*가정!$B$14)*가정!$B$15 -> 0.4267075 | T8: =MATCH(G8,등급!$B$4:$B$8,1)-1 -> 0
A9: megi | B9: 메기 | C9: 릴낚시 | E9: 30 | F9: 90 | G9: 70 | H9: 0.5 | I9: =(E9+F9)/2 -> 60 | J9: =MAX(1,ROUND(G9*(E9/I9)^2,0)) -> 18 | K9: =MAX(1,ROUND(G9*(F9/I9)^2,0)) -> 158 | L9: =G9*(E9^2+2*E9*(F9-E9)/(1+가정!$B$5)+(F9-E9)^2/(1+2*가정!$B$5))/I9^2 -> 57.717391 | M9: =INDEX(등급!$A$4:$A$8,MATCH(J9,등급!$B$4:$B$8,1)) -> 일반 | N9: =MATCH(K9,등급!$B$4:$B$8,1)-1 -> 1 | O9: =INDEX(등급!$A$4:$A$8,N9+1) -> 고급 | P9: =MIN(1,H9*가정!$B$24+(MATCH(J9,등급!$B$4:$B$8,1)-1)*가정!$B$25) -> 0.35 | Q9: =MIN(1,H9*가정!$B$24+N9*가정!$B$25+가정!$B$26) -> 0.52 | R9: =장비!$F$5*(1-Q9*가정!$B$14)*가정!$B$15 -> 0.20424 | S9: =장비!$F$9*(1-Q9*가정!$B$14)*가정!$B$15 -> 0.34891 | T9: =MATCH(G9,등급!$B$4:$B$8,1)-1 -> 1
A10: sogari | B10: 쏘가리 | C10: 릴낚시 | E10: 20 | F10: 55 | G10: 160 | H10: 0.55 | I10: =(E10+F10)/2 -> 37.5 | J10: =MAX(1,ROUND(G10*(E10/I10)^2,0)) -> 46 | K10: =MAX(1,ROUND(G10*(F10/I10)^2,0)) -> 344 | L10: =G10*(E10^2+2*E10*(F10-E10)/(1+가정!$B$5)+(F10-E10)^2/(1+2*가정!$B$5))/I10^2 -> 132.69952 | M10: =INDEX(등급!$A$4:$A$8,MATCH(J10,등급!$B$4:$B$8,1)) -> 일반 | N10: =MATCH(K10,등급!$B$4:$B$8,1)-1 -> 2 | O10: =INDEX(등급!$A$4:$A$8,N10+1) -> 희귀 | P10: =MIN(1,H10*가정!$B$24+(MATCH(J10,등급!$B$4:$B$8,1)-1)*가정!$B$25) -> 0.385 | Q10: =MIN(1,H10*가정!$B$24+N10*가정!$B$25+가정!$B$26) -> 0.605 | R10: =장비!$F$5*(1-Q10*가정!$B$14)*가정!$B$15 -> 0.19251 | S10: =장비!$F$9*(1-Q10*가정!$B$14)*가정!$B$15 -> 0.32887125 | T10: =MATCH(G10,등급!$B$4:$B$8,1)-1 -> 1
A11: jangeo | B11: 민물장어 | C11: 릴낚시 | E11: 40 | F11: 100 | G11: 400 | H11: 0.7 | I11: =(E11+F11)/2 -> 70 | J11: =MAX(1,ROUND(G11*(E11/I11)^2,0)) -> 131 | K11: =MAX(1,ROUND(G11*(F11/I11)^2,0)) -> 816 | L11: =G11*(E11^2+2*E11*(F11-E11)/(1+가정!$B$5)+(F11-E11)^2/(1+2*가정!$B$5))/I11^2 -> 334.44036 | M11: =INDEX(등급!$A$4:$A$8,MATCH(J11,등급!$B$4:$B$8,1)) -> 고급 | N11: =MATCH(K11,등급!$B$4:$B$8,1)-1 -> 3 | O11: =INDEX(등급!$A$4:$A$8,N11+1) -> 영웅 | P11: =MIN(1,H11*가정!$B$24+(MATCH(J11,등급!$B$4:$B$8,1)-1)*가정!$B$25) -> 0.54 | Q11: =MIN(1,H11*가정!$B$24+N11*가정!$B$25+가정!$B$26) -> 0.76 | R11: =장비!$F$5*(1-Q11*가정!$B$14)*가정!$B$15 -> 0.17112 | S11: =장비!$F$9*(1-Q11*가정!$B$14)*가정!$B$15 -> 0.29233 | T11: =MATCH(G11,등급!$B$4:$B$8,1)-1 -> 2
A12: cheolgap | B12: 철갑상어 | C12: 릴낚시 | E12: 80 | F12: 200 | G12: 1800 | H12: 0.9 | I12: =(E12+F12)/2 -> 140 | J12: =MAX(1,ROUND(G12*(E12/I12)^2,0)) -> 588 | K12: =MAX(1,ROUND(G12*(F12/I12)^2,0)) -> 3673 | L12: =G12*(E12^2+2*E12*(F12-E12)/(1+가정!$B$5)+(F12-E12)^2/(1+2*가정!$B$5))/I12^2 -> 1504.9816 | M12: =INDEX(등급!$A$4:$A$8,MATCH(J12,등급!$B$4:$B$8,1)) -> 희귀 | N12: =MATCH(K12,등급!$B$4:$B$8,1)-1 -> 4 | O12: =INDEX(등급!$A$4:$A$8,N12+1) -> 전설 | P12: =MIN(1,H12*가정!$B$24+(MATCH(J12,등급!$B$4:$B$8,1)-1)*가정!$B$25) -> 0.73 | Q12: =MIN(1,H12*가정!$B$24+N12*가정!$B$25+가정!$B$26) -> 0.95 | R12: =장비!$F$5*(1-Q12*가정!$B$14)*가정!$B$15 -> 0.1449 | S12: =장비!$F$9*(1-Q12*가정!$B$14)*가정!$B$15 -> 0.2475375 | T12: =MATCH(G12,등급!$B$4:$B$8,1)-1 -> 3
A13: mangdung | B13: 망둥어 | C13: 찌낚시 | E13: 8 | F13: 25 | G13: 15 | H13: 0.15 | I13: =(E13+F13)/2 -> 16.5 | J13: =MAX(1,ROUND(G13*(E13/I13)^2,0)) -> 4 | K13: =MAX(1,ROUND(G13*(F13/I13)^2,0)) -> 34 | L13: =G13*(E13^2+2*E13*(F13-E13)/(1+가정!$B$5)+(F13-E13)^2/(1+2*가정!$B$5))/I13^2 -> 12.339887 | M13: =INDEX(등급!$A$4:$A$8,MATCH(J13,등급!$B$4:$B$8,1)) -> 일반 | N13: =MATCH(K13,등급!$B$4:$B$8,1)-1 -> 0 | O13: =INDEX(등급!$A$4:$A$8,N13+1) -> 일반 | P13: =MIN(1,H13*가정!$B$24+(MATCH(J13,등급!$B$4:$B$8,1)-1)*가정!$B$25) -> 0.105 | Q13: =MIN(1,H13*가정!$B$24+N13*가정!$B$25+가정!$B$26) -> 0.225 | R13: =장비!$F$5*(1-Q13*가정!$B$14)*가정!$B$15 -> 0.24495 | S13: =장비!$F$9*(1-Q13*가정!$B$14)*가정!$B$15 -> 0.41845625 | T13: =MATCH(G13,등급!$B$4:$B$8,1)-1 -> 0
A14: jeongaengi | B14: 전갱이 | C14: 릴낚시 | E14: 15 | F14: 40 | G14: 35 | H14: 0.3 | I14: =(E14+F14)/2 -> 27.5 | J14: =MAX(1,ROUND(G14*(E14/I14)^2,0)) -> 10 | K14: =MAX(1,ROUND(G14*(F14/I14)^2,0)) -> 74 | L14: =G14*(E14^2+2*E14*(F14-E14)/(1+가정!$B$5)+(F14-E14)^2/(1+2*가정!$B$5))/I14^2 -> 29.098096 | M14: =INDEX(등급!$A$4:$A$8,MATCH(J14,등급!$B$4:$B$8,1)) -> 일반 | N14: =MATCH(K14,등급!$B$4:$B$8,1)-1 -> 1 | O14: =INDEX(등급!$A$4:$A$8,N14+1) -> 고급 | P14: =MIN(1,H14*가정!$B$24+(MATCH(J14,등급!$B$4:$B$8,1)-1)*가정!$B$25) -> 0.21 | Q14: =MIN(1,H14*가정!$B$24+N14*가정!$B$25+가정!$B$26) -> 0.38 | R14: =장비!$F$5*(1-Q14*가정!$B$14)*가정!$B$15 -> 0.22356 | S14: =장비!$F$9*(1-Q14*가정!$B$14)*가정!$B$15 -> 0.381915 | T14: =MATCH(G14,등급!$B$4:$B$8,1)-1 -> 0
A15: godeungeo | B15: 고등어 | C15: 릴낚시 | E15: 25 | F15: 50 | G15: 60 | H15: 0.4 | I15: =(E15+F15)/2 -> 37.5 | J15: =MAX(1,ROUND(G15*(E15/I15)^2,0)) -> 27 | K15: =MAX(1,ROUND(G15*(F15/I15)^2,0)) -> 107 | L15: =G15*(E15^2+2*E15*(F15-E15)/(1+가정!$B$5)+(F15-E15)^2/(1+2*가정!$B$5))/I15^2 -> 51.511387 | M15: =INDEX(등급!$A$4:$A$8,MATCH(J15,등급!$B$4:$B$8,1)) -> 일반 | N15: =MATCH(K15,등급!$B$4:$B$8,1)-1 -> 1 | O15: =INDEX(등급!$A$4:$A$8,N15+1) -> 고급 | P15: =MIN(1,H15*가정!$B$24+(MATCH(J15,등급!$B$4:$B$8,1)-1)*가정!$B$25) -> 0.28 | Q15: =MIN(1,H15*가정!$B$24+N15*가정!$B$25+가정!$B$26) -> 0.45 | R15: =장비!$F$5*(1-Q15*가정!$B$14)*가정!$B$15 -> 0.2139 | S15: =장비!$F$9*(1-Q15*가정!$B$14)*가정!$B$15 -> 0.3654125 | T15: =MATCH(G15,등급!$B$4:$B$8,1)-1 -> 1
A16: ureok | B16: 우럭 | C16: 찌낚시 | E16: 20 | F16: 50 | G16: 150 | H16: 0.45 | I16: =(E16+F16)/2 -> 35 | J16: =MAX(1,ROUND(G16*(E16/I16)^2,0)) -> 49 | K16: =MAX(1,ROUND(G16*(F16/I16)^2,0)) -> 306 | L16: =G16*(E16^2+2*E16*(F16-E16)/(1+가정!$B$5)+(F16-E16)^2/(1+2*가정!$B$5))/I16^2 -> 125.41513 | M16: =INDEX(등급!$A$4:$A$8,MATCH(J16,등급!$B$4:$B$8,1)) -> 일반 | N16: =MATCH(K16,등급!$B$4:$B$8,1)-1 -> 2 | O16: =INDEX(등급!$A$4:$A$8,N16+1) -> 희귀 | P16: =MIN(1,H16*가정!$B$24+(MATCH(J16,등급!$B$4:$B$8,1)-1)*가정!$B$25) -> 0.315 | Q16: =MIN(1,H16*가정!$B$24+N16*가정!$B$25+가정!$B$26) -> 0.535 | R16: =장비!$F$5*(1-Q16*가정!$B$14)*가정!$B$15 -> 0.20217 | S16: =장비!$F$9*(1-Q16*가정!$B$14)*가정!$B$15 -> 0.34537375 | T16: =MATCH(G16,등급!$B$4:$B$8,1)-1 -> 1
... A47: halibut | B47: 핼리벗 | C47: 릴낚시 | E47: 80 | F47: 250 | G47: 14000 | H47: 0.99 | I47: =(E47+F47)/2 -> 165 | J47: =MAX(1,ROUND(G47*(E47/I47)^2,0)) -> 3291 | K47: =MAX(1,ROUND(G47*(F47/I47)^2,0)) -> 32140 | L47: =G47*(E47^2+2*E47*(F47-E47)/(1+가정!$B$5)+(F47-E47)^2/(1+2*가정!$B$5))/I47^2 -> 11517.228 | M47: =INDEX(등급!$A$4:$A$8,MATCH(J47,등급!$B$4:$B$8,1)) -> 전설 | N47: =MATCH(K47,등급!$B$4:$B$8,1)-1 -> 4 | O47: =INDEX(등급!$A$4:$A$8,N47+1) -> 전설 | P47: =MIN(1,H47*가정!$B$24+(MATCH(J47,등급!$B$4:$B$8,1)-1)*가정!$B$25) -> 0.893 | Q47: =MIN(1,H47*가정!$B$24+N47*가정!$B$25+가정!$B$26) -> 1 | R47: =장비!$F$5*(1-Q47*가정!$B$14)*가정!$B$15 -> 0.138 | S47: =장비!$F$9*(1-Q47*가정!$B$14)*가정!$B$15 -> 0.23575 | T47: =MATCH(G47,등급!$B$4:$B$8,1)-1 -> 4
A48: hwanggeum | B48: 황금 고등어 | C48: 릴낚시 | D48: 예 | E48: 30 | F48: 55 | G48: 2500 | H48: 0.6 | I48: =(E48+F48)/2 -> 42.5 | J48: =MAX(1,ROUND(G48*(E48/I48)^2,0)) -> 1246 | K48: =MAX(1,ROUND(G48*(F48/I48)^2,0)) -> 4187 | L48: =G48*(E48^2+2*E48*(F48-E48)/(1+가정!$B$5)+(F48-E48)^2/(1+2*가정!$B$5))/I48^2 -> 2175.2026 | M48: =INDEX(등급!$A$4:$A$8,MATCH(J48,등급!$B$4:$B$8,1)) -> 영웅 | N48: =MATCH(K48,등급!$B$4:$B$8,1)-1 -> 4 | O48: =INDEX(등급!$A$4:$A$8,N48+1) -> 전설 | P48: =MIN(1,H48*가정!$B$24+(MATCH(J48,등급!$B$4:$B$8,1)-1)*가정!$B$25) -> 0.57 | Q48: =MIN(1,H48*가정!$B$24+N48*가정!$B$25+가정!$B$26) -> 0.74 | R48: =장비!$F$5*(1-Q48*가정!$B$14)*가정!$B$15 -> 0.17388 | S48: =장비!$F$9*(1-Q48*가정!$B$14)*가정!$B$15 -> 0.297045 | T48: =MATCH(G48,등급!$B$4:$B$8,1)-1 -> 4
A49: eungalchi | B49: 해운대 은갈치 | C49: 릴낚시 | D49: 예 | E49: 90 | F49: 180 | G49: 1800 | H49: 0.55 | I49: =(E49+F49)/2 -> 135 | J49: =MAX(1,ROUND(G49*(E49/I49)^2,0)) -> 800 | K49: =MAX(1,ROUND(G49*(F49/I49)^2,0)) -> 3200 | L49: =G49*(E49^2+2*E49*(F49-E49)/(1+가정!$B$5)+(F49-E49)^2/(1+2*가정!$B$5))/I49^2 -> 1545.3416 | M49: =INDEX(등급!$A$4:$A$8,MATCH(J49,등급!$B$4:$B$8,1)) -> 영웅 | N49: =MATCH(K49,등급!$B$4:$B$8,1)-1 -> 4 | O49: =INDEX(등급!$A$4:$A$8,N49+1) -> 전설 | P49: =MIN(1,H49*가정!$B$24+(MATCH(J49,등급!$B$4:$B$8,1)-1)*가정!$B$25) -> 0.535 | Q49: =MIN(1,H49*가정!$B$24+N49*가정!$B$25+가정!$B$26) -> 0.705 | R49: =장비!$F$5*(1-Q49*가정!$B$14)*가정!$B$15 -> 0.17871 | S49: =장비!$F$9*(1-Q49*가정!$B$14)*가정!$B$15 -> 0.30529625 | T49: =MATCH(G49,등급!$B$4:$B$8,1)-1 -> 3
A50: dageumbari | B50: 태종대 다금바리 | C50: 찌낚시 | D50: 예 | E50: 50 | F50: 120 | G50: 6000 | H50: 0.85 | I50: =(E50+F50)/2 -> 85 | J50: =MAX(1,ROUND(G50*(E50/I50)^2,0)) -> 2076 | K50: =MAX(1,ROUND(G50*(F50/I50)^2,0)) -> 11958 | L50: =G50*(E50^2+2*E50*(F50-E50)/(1+가정!$B$5)+(F50-E50)^2/(1+2*가정!$B$5))/I50^2 -> 5036.8587 | M50: =INDEX(등급!$A$4:$A$8,MATCH(J50,등급!$B$4:$B$8,1)) -> 영웅 | N50: =MATCH(K50,등급!$B$4:$B$8,1)-1 -> 4 | O50: =INDEX(등급!$A$4:$A$8,N50+1) -> 전설 | P50: =MIN(1,H50*가정!$B$24+(MATCH(J50,등급!$B$4:$B$8,1)-1)*가정!$B$25) -> 0.745 | Q50: =MIN(1,H50*가정!$B$24+N50*가정!$B$25+가정!$B$26) -> 0.915 | R50: =장비!$F$5*(1-Q50*가정!$B$14)*가정!$B$15 -> 0.14973 | S50: =장비!$F$9*(1-Q50*가정!$B$14)*가정!$B$15 -> 0.25578875 | T50: =MATCH(G50,등급!$B$4:$B$8,1)-1 -> 4
A51: dotdom | B51: 오륙도 돗돔 | C51: 릴낚시 | D51: 예 | E51: 100 | F51: 220 | G51: 20000 | H51: 0.99 | I51: =(E51+F51)/2 -> 160 | J51: =MAX(1,ROUND(G51*(E51/I51)^2,0)) -> 7813 | K51: =MAX(1,ROUND(G51*(F51/I51)^2,0)) -> 37813 | L51: =G51*(E51^2+2*E51*(F51-E51)/(1+가정!$B$5)+(F51-E51)^2/(1+2*가정!$B$5))/I51^2 -> 16954.581 | M51: =INDEX(등급!$A$4:$A$8,MATCH(J51,등급!$B$4:$B$8,1)) -> 전설 | N51: =MATCH(K51,등급!$B$4:$B$8,1)-1 -> 4 | O51: =INDEX(등급!$A$4:$A$8,N51+1) -> 전설 | P51: =MIN(1,H51*가정!$B$24+(MATCH(J51,등급!$B$4:$B$8,1)-1)*가정!$B$25) -> 0.893 | Q51: =MIN(1,H51*가정!$B$24+N51*가정!$B$25+가정!$B$26) -> 1 | R51: =장비!$F$5*(1-Q51*가정!$B$14)*가정!$B$15 -> 0.138 | S51: =장비!$F$9*(1-Q51*가정!$B$14)*가정!$B$15 -> 0.23575 | T51: =MATCH(G51,등급!$B$4:$B$8,1)-1 -> 4

Sheet 낚시터
A1: 낚시터별 출현표
A2: 출현 확률 = 가중치 ÷ 같은 낚시터 가중치 합. 부캉이, 방식 출현 배수, 미끼 행운은 빼고 떡밥·방식 무관 기준입니다.
A4: 번호 | B4: 낚시터 | C4: 해금 비용 (원) | D4: 추천 방식 | E4: 출현 종 수 | F4: 1마리 기대 판매가 (원) | G4: 다음 낚시터 해금까지 기대 마릿수 | H4: 전설 등급이 나올 수 있는 종 | I4: 기대 판매가 가장 가까이 (원) | J4: 기대 판매가 가장 멀리 (원)
A5: 0 | B5: 실내 낚시터 | C5: 0 | D5: 찌낚시 | E5: =COUNTIF($A$18:$A$74,B5) -> 3 | F5: =SUMIF($A$18:$A$74,B5,$G$18:$G$74) -> 15.956293 | G5: =ROUNDUP((C6-가정!$B$12)/F5,0) -> 0 | H5: =COUNTIFS($A$18:$A$74,B5,$I$18:$I$74,"전설") -> 0 | I5: =SUMIF($A$18:$A$74,B5,$M$18:$M$74) -> 15.510734 | J5: =SUMIF($A$18:$A$74,B5,$N$18:$N$74) -> 16.53979
A6: 1 | B6: 하천 | C6: 150 | D6: 찌낚시 | E6: =COUNTIF($A$18:$A$74,B6) -> 6 | F6: =SUMIF($A$18:$A$74,B6,$G$18:$G$74) -> 22.906001 | G6: =ROUNDUP(C7/F6,0) -> 27 | H6: =COUNTIFS($A$18:$A$74,B6,$I$18:$I$74,"전설") -> 0 | I6: =SUMIF($A$18:$A$74,B6,$M$18:$M$74) -> 19.99543 | J6: =SUMIF($A$18:$A$74,B6,$N$18:$N$74) -> 26.422127
A7: 2 | B7: 강 | C7: 600 | D7: 찌낚시 | E7: =COUNTIF($A$18:$A$74,B7) -> 7 | F7: =SUMIF($A$18:$A$74,B7,$G$18:$G$74) -> 47.014867 | G7: =ROUNDUP(C8/F7,0) -> 32 | H7: =COUNTIFS($A$18:$A$74,B7,$I$18:$I$74,"전설") -> 1 | I7: =SUMIF($A$18:$A$74,B7,$M$18:$M$74) -> 34.616648 | J7: =SUMIF($A$18:$A$74,B7,$N$18:$N$74) -> 66.716021
A8: 3 | B8: 방파제 | C8: 1500 | D8: 찌낚시 | E8: =COUNTIF($A$18:$A$74,B8) -> 8 | F8: =SUMIF($A$18:$A$74,B8,$G$18:$G$74) -> 122.22154 | G8: =ROUNDUP(C9/F8,0) -> 25 | H8: =COUNTIFS($A$18:$A$74,B8,$I$18:$I$74,"전설") -> 1 | I8: =SUMIF($A$18:$A$74,B8,$M$18:$M$74) -> 88.479382 | J8: =SUMIF($A$18:$A$74,B8,$N$18:$N$74) -> 168.29829
A9: 4 | B9: 독도 | C9: 3000 | D9: 찌낚시 | E9: =COUNTIF($A$18:$A$74,B9) -> 7 | F9: =SUMIF($A$18:$A$74,B9,$G$18:$G$74) -> 269.42919 | G9: =ROUNDUP(C10/F9,0) -> 30 | H9: =COUNTIFS($A$18:$A$74,B9,$I$18:$I$74,"전설") -> 2 | I9: =SUMIF($A$18:$A$74,B9,$M$18:$M$74) -> 224.41454 | J9: =SUMIF($A$18:$A$74,B9,$N$18:$N$74) -> 332.3128
A10: 5 | B10: 배낚시 | C10: 8000 | D10: 릴낚시 | E10: =COUNTIF($A$18:$A$74,B10) -> 6 | F10: =SUMIF($A$18:$A$74,B10,$G$18:$G$74) -> 758.26928 | G10: =ROUNDUP(C11/F10,0) -> 33 | H10: =COUNTIFS($A$18:$A$74,B10,$I$18:$I$74,"전설") -> 3 | I10: =SUMIF($A$18:$A$74,B10,$M$18:$M$74) -> 588.25844 | J10: =SUMIF($A$18:$A$74,B10,$N$18:$N$74) -> 959.73527
A11: 6 | B11: 아마존 | C11: 25000 | D11: 릴낚시 | E11: =COUNTIF($A$18:$A$74,B11) -> 6 | F11: =SUMIF($A$18:$A$74,B11,$G$18:$G$74) -> 1261.8303 | G11: =ROUNDUP(C12/F11,0) -> 40 | H11: =COUNTIFS($A$18:$A$74,B11,$I$18:$I$74,"전설") -> 4 | I11: =SUMIF($A$18:$A$74,B11,$M$18:$M$74) -> 1031.2538 | J11: =SUMIF($A$18:$A$74,B11,$N$18:$N$74) -> 1519.3772
A12: 7 | B12: 알래스카 | C12: 50000 | D12: 릴낚시 | E12: =COUNTIF($A$18:$A$74,B12) -> 7 | F12: =SUMIF($A$18:$A$74,B12,$G$18:$G$74) -> 2008.837 | G12: - | H12: =COUNTIFS($A$18:$A$74,B12,$I$18:$I$74,"전설") -> 6 | I12: =SUMIF($A$18:$A$74,B12,$M$18:$M$74) -> 1884.1082 | J12: =SUMIF($A$18:$A$74,B12,$N$18:$N$74) -> 2158.4153
A13: SP | B13: 부산 | C13: 부산 이용권 1장 | D13: 릴낚시 | E13: =COUNTIF($A$18:$A$74,B13) -> 7 | F13: =SUMIF($A$18:$A$74,B13,$G$18:$G$74) -> 1944.8077 | G13: - | H13: =COUNTIFS($A$18:$A$74,B13,$I$18:$I$74,"전설") -> 6 | I13: =SUMIF($A$18:$A$74,B13,$M$18:$M$74) -> 1806.8439 | J13: =SUMIF($A$18:$A$74,B13,$N$18:$N$74) -> 2104.8386
A16: 출현 상세
A17: 낚시터 | B17: 물고기 ID | C17: 이름 | D17: 선호 방식 | E17: 가중치 | F17: 출현 확률 | G17: 기대 판매가 기여 (확률×기대가, 원) | H17: 1마리 기대 판매가 (원) | I17: 최대 등급 | J17: 가중치 가장 가까이 | K17: 가중치 가장 멀리 | M17: 기여 가장 가까이 (원) | N17: 기여 가장 멀리 (원) | O17: 최소 길이 (cm) | P17: 최대 길이 (cm) | Q17: 기준가 (원) | R17: 평균 길이 (cm) | S17: 기준가 등급 번호
A18: 실내 낚시터 | B18: bungeo | C18: =물고기!B5 -> 붕어 | D18: =물고기!C5 -> 찌낚시 | E18: 70 | F18: =E18/SUMIF($A$18:$A$74,A18,$E$18:$E$74) -> 0.7 | G18: =F18*H18 -> 7.0232476 | H18: =물고기!L5 -> 10.033211 | I18: =물고기!O5 -> 일반 | J18: =E18*(1+가정!$B$27)^(-물고기!T5) -> 70 | K18: =E18*(1+가정!$B$27)^(물고기!T5) -> 70 | M18: =J18/SUMIF($A$18:$A$74,A18,$J$18:$J$74)*H18 -> 7.1154853 | N18: =K18/SUMIF($A$18:$A$74,A18,$K$18:$K$74)*H18 -> 6.9024546 | O18: =물고기!E5 -> 12 | P18: =물고기!F5 -> 30 | Q18: =물고기!G5 -> 12 | R18: =물고기!I5 -> 21 | S18: =물고기!T5 -> 0
A19: 실내 낚시터 | B19: hyangeo | C19: =물고기!B6 -> 향어 | D19: =물고기!C6 -> 찌낚시 | E19: 25 | F19: =E19/SUMIF($A$18:$A$74,A19,$E$18:$E$74) -> 0.25 | G19: =F19*H19 -> 6.4389234 | H19: =물고기!L6 -> 25.755694 | I19: =물고기!O6 -> 일반 | J19: =E19*(1+가정!$B$27)^(-물고기!T6) -> 25 | K19: =E19*(1+가정!$B$27)^(물고기!T6) -> 25 | M19: =J19/SUMIF($A$18:$A$74,A19,$J$18:$J$74)*H19 -> 6.5234871 | N19: =K19/SUMIF($A$18:$A$74,A19,$K$18:$K$74)*H19 -> 6.3281802 | O19: =물고기!E6 -> 25 | P19: =물고기!F6 -> 50 | Q19: =물고기!G6 -> 30 | R19: =물고기!I6 -> 37.5 | S19: =물고기!T6 -> 0
A20: 실내 낚시터 | B20: ingeo | C20: =물고기!B7 -> 잉어 | D20: =물고기!C7 -> 찌낚시 | E20: 5 | F20: =E20/SUMIF($A$18:$A$74,A20,$E$18:$E$74) -> 0.05 | G20: =F20*H20 -> 2.4941225 | H20: =물고기!L7 -> 49.88245 | I20: =물고기!O7 -> 고급 | J20: =E20*(1+가정!$B$27)^(-물고기!T7) -> 3.7037037 | K20: =E20*(1+가정!$B$27)^(물고기!T7) -> 6.75 | M20: =J20/SUMIF($A$18:$A$74,A20,$J$18:$J$74)*H20 -> 1.8717617 | N20: =K20/SUMIF($A$18:$A$74,A20,$K$18:$K$74)*H20 -> 3.3091551 | O20: =물고기!E7 -> 30 | P20: =물고기!F7 -> 80 | Q20: =물고기!G7 -> 60 | R20: =물고기!I7 -> 55 | S20: =물고기!T7 -> 1
A21: 하천 | B21: beodeulchi | C21: =물고기!B27 -> 버들치 | D21: =물고기!C27 -> 찌낚시 | E21: 25 | F21: =E21/SUMIF($A$18:$A$74,A21,$E$18:$E$74) -> 0.25510204 | G21: =F21*H21 -> 1.7132173 | H21: =물고기!L27 -> 6.7158116 | I21: =물고기!O27 -> 일반 | J21: =E21*(1+가정!$B$27)^(-물고기!T27) -> 25 | K21: =E21*(1+가정!$B$27)^(물고기!T27) -> 25 | M21: =J21/SUMIF($A$18:$A$74,A21,$J$18:$J$74)*H21 -> 1.7988781 | N21: =K21/SUMIF($A$18:$A$74,A21,$K$18:$K$74)*H21 -> 1.6097343 | O21: =물고기!E27 -> 5 | P21: =물고기!F27 -> 12 | Q21: =물고기!G27 -> 8 | R21: =물고기!I27 -> 8.5 | S21: =물고기!T27 -> 0
A22: 하천 | B22: pirami | C22: =물고기!B8 -> 피라미 | D22: =물고기!C8 -> 찌낚시 | E22: 20 | F22: =E22/SUMIF($A$18:$A$74,A22,$E$18:$E$74) -> 0.20408163 | G22: =F22*H22 -> 1.023797 | H22: =물고기!L8 -> 5.0166054 | I22: =물고기!O8 -> 일반 | J22: =E22*(1+가정!$B$27)^(-물고기!T8) -> 20 | K22: =E22*(1+가정!$B$27)^(물고기!T8) -> 20 | M22: =J22/SUMIF($A$18:$A$74,A22,$J$18:$J$74)*H22 -> 1.0749869 | N22: =K22/SUMIF($A$18:$A$74,A22,$K$18:$K$74)*H22 -> 0.96195693 | O22: =물고기!E8 -> 6 | P22: =물고기!F8 -> 15 | Q22: =물고기!G8 -> 6 | R22: =물고기!I8 -> 10.5 | S22: =물고기!T8 -> 0
A23: 하천 | B23: galgyeoni | C23: =물고기!B28 -> 갈겨니 | D23: =물고기!C28 -> 찌낚시 | E23: 20 | F23: =E23/SUMIF($A$18:$A$74,A23,$E$18:$E$74) -> 0.20408163 | G23: =F23*H23 -> 2.0705034 | H23: =물고기!L28 -> 10.145467 | I23: =물고기!O28 -> 일반 | J23: =E23*(1+가정!$B$27)^(-물고기!T28) -> 20 | K23: =E23*(1+가정!$B$27)^(물고기!T28) -> 20 | M23: =J23/SUMIF($A$18:$A$74,A23,$J$18:$J$74)*H23 -> 2.1740286 | N23: =K23/SUMIF($A$18:$A$74,A23,$K$18:$K$74)*H23 -> 1.9454394 | O23: =물고기!E28 -> 8 | P23: =물고기!F28 -> 18 | Q23: =물고기!G28 -> 12 | R23: =물고기!I28 -> 13 | S23: =물고기!T28 -> 0
A24: 하천 | B24: molaemuji | C24: =물고기!B29 -> 모래무지 | D24: =물고기!C29 -> 찌낚시 | E24: 15 | F24: =E24/SUMIF($A$18:$A$74,A24,$E$18:$E$74) -> 0.15306122 | G24: =F24*H24 -> 3.1993657 | H24: =물고기!L29 -> 20.902522 | I24: =물고기!O29 -> 일반 | J24: =E24*(1+가정!$B$27)^(-물고기!T29) -> 15 | K24: =E24*(1+가정!$B$27)^(물고기!T29) -> 15 | M24: =J24/SUMIF($A$18:$A$74,A24,$J$18:$J$74)*H24 -> 3.359334 | N24: =K24/SUMIF($A$18:$A$74,A24,$K$18:$K$74)*H24 -> 3.0061154 | O24: =물고기!E29 -> 10 | P24: =물고기!F29 -> 25 | Q24: =물고기!G29 -> 25 | R24: =물고기!I29 -> 17.5 | S24: =물고기!T29 -> 0
A25: 하천 | B25: kkeokji | C25: =물고기!B30 -> 꺽지 | D25: =물고기!C30 -> 릴낚시 | E25: 12 | F25: =E25/SUMIF($A$18:$A$74,A25,$E$18:$E$74) -> 0.12244898 | G25: =F25*H25 -> 7.1665791 | H25: =물고기!L30 -> 58.527063 | I25: =물고기!O30 -> 고급 | J25: =E25*(1+가정!$B$27)^(-물고기!T30) -> 8.8888889 | K25: =E25*(1+가정!$B$27)^(물고기!T30) -> 16.2 | M25: =J25/SUMIF($A$18:$A$74,A25,$J$18:$J$74)*H25 -> 5.574006 | N25: =K25/SUMIF($A$18:$A$74,A25,$K$18:$K$74)*H25 -> 9.090493 | O25: =물고기!E30 -> 10 | P25: =물고기!F30 -> 25 | Q25: =물고기!G30 -> 70 | R25: =물고기!I30 -> 17.5 | S25: =물고기!T30 -> 1
A26: 하천 | B26: euneo | C26: =물고기!B31 -> 은어 | D26: =물고기!C31 -> 릴낚시 | E26: 6 | F26: =E26/SUMIF($A$18:$A$74,A26,$E$18:$E$74) -> 0.06122449 | G26: =F26*H26 -> 7.732539 | H26: =물고기!L31 -> 126.29814 | I26: =물고기!O31 -> 희귀 | J26: =E26*(1+가정!$B$27)^(-물고기!T31) -> 4.4444444 | K26: =E26*(1+가정!$B$27)^(물고기!T31) -> 8.1 | M26: =J26/SUMIF($A$18:$A$74,A26,$J$18:$J$74)*H26 -> 6.014197 | N26: =K26/SUMIF($A$18:$A$74,A26,$K$18:$K$74)*H26 -> 9.8083884 | O26: =물고기!E31 -> 12 | P26: =물고기!F31 -> 28 | Q26: =물고기!G31 -> 150 | R26: =물고기!I31 -> 20 | S26: =물고기!T31 -> 1
A27: 강 | B27: pirami | C27: =물고기!B8 -> 피라미 | D27: =물고기!C8 -> 찌낚시 | E27: 35 | F27: =E27/SUMIF($A$18:$A$74,A27,$E$18:$E$74) -> 0.35140562 | G27: =F27*H27 -> 1.7628633 | H27: =물고기!L8 -> 5.0166054 | I27: =물고기!O8 -> 일반 | J27: =E27*(1+가정!$B$27)^(-물고기!T8) -> 35 | K27: =E27*(1+가정!$B$27)^(물고기!T8) -> 35 | M27: =J27/SUMIF($A$18:$A$74,A27,$J$18:$J$74)*H27 -> 1.9654376 | N27: =K27/SUMIF($A$18:$A$74,A27,$K$18:$K$74)*H27 -> 1.5335442 | O27: =물고기!E8 -> 6 | P27: =물고기!F8 -> 15 | Q27: =물고기!G8 -> 6 | R27: =물고기!I8 -> 10.5 | S27: =물고기!T8 -> 0
A28: 강 | B28: bungeo | C28: =물고기!B5 -> 붕어 | D28: =물고기!C5 -> 찌낚시 | E28: 28 | F28: =E28/SUMIF($A$18:$A$74,A28,$E$18:$E$74) -> 0.2811245 | G28: =F28*H28 -> 2.8205813 | H28: =물고기!L5 -> 10.033211 | I28: =물고기!O5 -> 일반 | J28: =E28*(1+가정!$B$27)^(-물고기!T5) -> 28 | K28: =E28*(1+가정!$B$27)^(물고기!T5) -> 28 | M28: =J28/SUMIF($A$18:$A$74,A28,$J$18:$J$74)*H28 -> 3.1447002 | N28: =K28/SUMIF($A$18:$A$74,A28,$K$18:$K$74)*H28 -> 2.4536707 | O28: =물고기!E5 -> 12 | P28: =물고기!F5 -> 30 | Q28: =물고기!G5 -> 12 | R28: =물고기!I5 -> 21 | S28: =물고기!T5 -> 0
A29: 강 | B29: ingeo | C29: =물고기!B7 -> 잉어 | D29: =물고기!C7 -> 찌낚시 | E29: 14 | F29: =E29/SUMIF($A$18:$A$74,A29,$E$18:$E$74) -> 0.14056225 | G29: =F29*H29 -> 7.0115893 | H29: =물고기!L7 -> 49.88245 | I29: =물고기!O7 -> 고급 | J29: =E29*(1+가정!$B$27)^(-물고기!T7) -> 10.37037 | K29: =E29*(1+가정!$B$27)^(물고기!T7) -> 18.9 | M29: =J29/SUMIF($A$18:$A$74,A29,$J$18:$J$74)*H29 -> 5.7905966 | N29: =K29/SUMIF($A$18:$A$74,A29,$K$18:$K$74)*H29 -> 8.2343229 | O29: =물고기!E7 -> 30 | P29: =물고기!F7 -> 80 | Q29: =물고기!G7 -> 60 | R29: =물고기!I7 -> 55 | S29: =물고기!T7 -> 1
A30: 강 | B30: megi | C30: =물고기!B9 -> 메기 | D30: =물고기!C9 -> 릴낚시 | E30: 12 | F30: =E30/SUMIF($A$18:$A$74,A30,$E$18:$E$74) -> 0.12048193 | G30: =F30*H30 -> 6.9539026 | H30: =물고기!L9 -> 57.717391 | I30: =물고기!O9 -> 고급 | J30: =E30*(1+가정!$B$27)^(-물고기!T9) -> 8.8888889 | K30: =E30*(1+가정!$B$27)^(물고기!T9) -> 16.2 | M30: =J30/SUMIF($A$18:$A$74,A30,$J$18:$J$74)*H30 -> 5.7429554 | N30: =K30/SUMIF($A$18:$A$74,A30,$K$18:$K$74)*H30 -> 8.1665763 | O30: =물고기!E9 -> 30 | P30: =물고기!F9 -> 90 | Q30: =물고기!G9 -> 70 | R30: =물고기!I9 -> 60 | S30: =물고기!T9 -> 1
A31: 강 | B31: sogari | C31: =물고기!B10 -> 쏘가리 | D31: =물고기!C10 -> 릴낚시 | E31: 7 | F31: =E31/SUMIF($A$18:$A$74,A31,$E$18:$E$74) -> 0.070281124 | G31: =F31*H31 -> 9.3262713 | H31: =물고기!L10 -> 132.69952 | I31: =물고기!O10 -> 희귀 | J31: =E31*(1+가정!$B$27)^(-물고기!T10) -> 5.1851852 | K31: =E31*(1+가정!$B$27)^(물고기!T10) -> 9.45 | M31: =J31/SUMIF($A$18:$A$74,A31,$J$18:$J$74)*H31 -> 7.7022017 | N31: =K31/SUMIF($A$18:$A$74,A31,$K$18:$K$74)*H31 -> 10.952656 | O31: =물고기!E10 -> 20 | P31: =물고기!F10 -> 55 | Q31: =물고기!G10 -> 160 | R31: =물고기!I10 -> 37.5 | S31: =물고기!T10 -> 1
A32: 강 | B32: jangeo | C32: =물고기!B11 -> 민물장어 | D32: =물고기!C11 -> 릴낚시 | E32: 3 | F32: =E32/SUMIF($A$18:$A$74,A32,$E$18:$E$74) -> 0.030120482 | G32: =F32*H32 -> 10.073505 | H32: =물고기!L11 -> 334.44036 | I32: =물고기!O11 -> 영웅 | J32: =E32*(1+가정!$B$27)^(-물고기!T11) -> 1.6460905 | K32: =E32*(1+가정!$B$27)^(물고기!T11) -> 5.4675 | M32: =J32/SUMIF($A$18:$A$74,A32,$J$18:$J$74)*H32 -> 6.1624538 | N32: =K32/SUMIF($A$18:$A$74,A32,$K$18:$K$74)*H32 -> 15.970768 | O32: =물고기!E11 -> 40 | P32: =물고기!F11 -> 100 | Q32: =물고기!G11 -> 400 | R32: =물고기!I11 -> 70 | S32: =물고기!T11 -> 2
A33: 강 | B33: cheolgap | C33: =물고기!B12 -> 철갑상어 | D33: =물고기!C12 -> 릴낚시 | E33: 0.6 | F33: =E33/SUMIF($A$18:$A$74,A33,$E$18:$E$74) -> 0.0060240964 | G33: =F33*H33 -> 9.0661543 | H33: =물고기!L12 -> 1504.9816 | I33: =물고기!O12 -> 전설 | J33: =E33*(1+가정!$B$27)^(-물고기!T12) -> 0.24386526 | K33: =E33*(1+가정!$B$27)^(물고기!T12) -> 1.476225 | M33: =J33/SUMIF($A$18:$A$74,A33,$J$18:$J$74)*H33 -> 4.1083025 | N33: =K33/SUMIF($A$18:$A$74,A33,$K$18:$K$74)*H33 -> 19.404483 | O33: =물고기!E12 -> 80 | P33: =물고기!F12 -> 200 | Q33: =물고기!G12 -> 1800 | R33: =물고기!I12 -> 140 | S33: =물고기!T12 -> 3
A34: 방파제 | B34: mangdung | C34: =물고기!B13 -> 망둥어 | D34: =물고기!C13 -> 찌낚시 | E34: 30 | F34: =E34/SUMIF($A$18:$A$74,A34,$E$18:$E$74) -> 0.30150754 | G34: =F34*H34 -> 3.7205689 | H34: =물고기!L13 -> 12.339887 | I34: =물고기!O13 -> 일반 | J34: =E34*(1+가정!$B$27)^(-물고기!T13) -> 30 | K34: =E34*(1+가정!$B$27)^(물고기!T13) -> 30 | M34: =J34/SUMIF($A$18:$A$74,A34,$J$18:$J$74)*H34 -> 4.4238413 | N34: =K34/SUMIF($A$18:$A$74,A34,$K$18:$K$74)*H34 -> 2.9608237 | O34: =물고기!E13 -> 8 | P34: =물고기!F13 -> 25 | Q34: =물고기!G13 -> 15 | R34: =물고기!I13 -> 16.5 | S34: =물고기!T13 -> 0
A35: 방파제 | B35: jeongaengi | C35: =물고기!B14 -> 전갱이 | D35: =물고기!C14 -> 릴낚시 | E35: 22 | F35: =E35/SUMIF($A$18:$A$74,A35,$E$18:$E$74) -> 0.22110553 | G35: =F35*H35 -> 6.4337498 | H35: =물고기!L14 -> 29.098096 | I35: =물고기!O14 -> 고급 | J35: =E35*(1+가정!$B$27)^(-물고기!T14) -> 22 | K35: =E35*(1+가정!$B$27)^(물고기!T14) -> 22 | M35: =J35/SUMIF($A$18:$A$74,A35,$J$18:$J$74)*H35 -> 7.6498753 | N35: =K35/SUMIF($A$18:$A$74,A35,$K$18:$K$74)*H35 -> 5.1199695 | O35: =물고기!E14 -> 15 | P35: =물고기!F14 -> 40 | Q35: =물고기!G14 -> 35 | R35: =물고기!I14 -> 27.5 | S35: =물고기!T14 -> 0
A36: 방파제 | B36: godeungeo | C36: =물고기!B15 -> 고등어 | D36: =물고기!C15 -> 릴낚시 | E36: 18 | F36: =E36/SUMIF($A$18:$A$74,A36,$E$18:$E$74) -> 0.18090452 | G36: =F36*H36 -> 9.3186429 | H36: =물고기!L15 -> 51.511387 | I36: =물고기!O15 -> 고급 | J36: =E36*(1+가정!$B$27)^(-물고기!T15) -> 13.333333 | K36: =E36*(1+가정!$B$27)^(물고기!T15) -> 24.3 | M36: =J36/SUMIF($A$18:$A$74,A36,$J$18:$J$74)*H36 -> 8.2074659 | N36: =K36/SUMIF($A$18:$A$74,A36,$K$18:$K$74)*H36 -> 10.011281 | O36: =물고기!E15 -> 25 | P36: =물고기!F15 -> 50 | Q36: =물고기!G15 -> 60 | R36: =물고기!I15 -> 37.5 | S36: =물고기!T15 -> 1
A37: 방파제 | B37: ureok | C37: =물고기!B16 -> 우럭 | D37: =물고기!C16 -> 찌낚시 | E37: 12 | F37: =E37/SUMIF($A$18:$A$74,A37,$E$18:$E$74) -> 0.12060302 | G37: =F37*H37 -> 15.125443 | H37: =물고기!L16 -> 125.41513 | I37: =물고기!O16 -> 희귀 | J37: =E37*(1+가정!$B$27)^(-물고기!T16) -> 8.8888889 | K37: =E37*(1+가정!$B$27)^(물고기!T16) -> 16.2 | M37: =J37/SUMIF($A$18:$A$74,A37,$J$18:$J$74)*H37 -> 13.32185 | N37: =K37/SUMIF($A$18:$A$74,A37,$K$18:$K$74)*H37 -> 16.24969 | O37: =물고기!E16 -> 20 | P37: =물고기!F16 -> 50 | Q37: =물고기!G16 -> 150 | R37: =물고기!I16 -> 35 | S37: =물고기!T16 -> 1
A38: 방파제 | B38: gamseong | C38: =물고기!B17 -> 감성돔 | D38: =물고기!C17 -> 찌낚시 | E38: 8 | F38: =E38/SUMIF($A$18:$A$74,A38,$E$18:$E$74) -> 0.08040201 | G38: =F38*H38 -> 30.373017 | H38: =물고기!L17 -> 377.7644 | I38: =물고기!O17 -> 영웅 | J38: =E38*(1+가정!$B$27)^(-물고기!T17) -> 4.3895748 | K38: =E38*(1+가정!$B$27)^(물고기!T17) -> 14.58 | M38: =J38/SUMIF($A$18:$A$74,A38,$J$18:$J$74)*H38 -> 19.815753 | N38: =K38/SUMIF($A$18:$A$74,A38,$K$18:$K$74)*H38 -> 44.051295 | O38: =물고기!E17 -> 25 | P38: =물고기!F17 -> 60 | Q38: =물고기!G17 -> 450 | R38: =물고기!I17 -> 42.5 | S38: =물고기!T17 -> 2
A39: 방파제 | B39: nongeo | C39: =물고기!B18 -> 농어 | D39: =물고기!C18 -> 릴낚시 | E39: 5 | F39: =E39/SUMIF($A$18:$A$74,A39,$E$18:$E$74) -> 0.050251256 | G39: =F39*H39 -> 27.309828 | H39: =물고기!L18 -> 543.46558 | I39: =물고기!O18 -> 영웅 | J39: =E39*(1+가정!$B$27)^(-물고기!T18) -> 2.7434842 | K39: =E39*(1+가정!$B$27)^(물고기!T18) -> 9.1125 | M39: =J39/SUMIF($A$18:$A$74,A39,$J$18:$J$74)*H39 -> 17.817289 | N39: =K39/SUMIF($A$18:$A$74,A39,$K$18:$K$74)*H39 -> 39.60862 | O39: =물고기!E18 -> 40 | P39: =물고기!F18 -> 100 | Q39: =물고기!G18 -> 650 | R39: =물고기!I18 -> 70 | S39: =물고기!T18 -> 2
A40: 방파제 | B40: bengedom | C40: =물고기!B19 -> 벵에돔 | D40: =물고기!C19 -> 찌낚시 | E40: 3.5 | F40: =E40/SUMIF($A$18:$A$74,A40,$E$18:$E$74) -> 0.035175879 | G40: =F40*H40 -> 16.400788 | H40: =물고기!L19 -> 466.25097 | I40: =물고기!O19 -> 영웅 | J40: =E40*(1+가정!$B$27)^(-물고기!T19) -> 1.920439 | K40: =E40*(1+가정!$B$27)^(물고기!T19) -> 6.37875 | M40: =J40/SUMIF($A$18:$A$74,A40,$J$18:$J$74)*H40 -> 10.700088 | N40: =K40/SUMIF($A$18:$A$74,A40,$K$18:$K$74)*H40 -> 23.786769 | O40: =물고기!E19 -> 25 | P40: =물고기!F19 -> 55 | Q40: =물고기!G19 -> 550 | R40: =물고기!I19 -> 40 | S40: =물고기!T19 -> 2
A41: 방파제 | B41: doldom | C41: =물고기!B20 -> 돌돔 | D41: =물고기!C20 -> 찌낚시 | E41: 1 | F41: =E41/SUMIF($A$18:$A$74,A41,$E$18:$E$74) -> 0.010050251 | G41: =F41*H41 -> 13.539499 | H41: =물고기!L20 -> 1347.1801 | I41: =물고기!O20 -> 전설 | J41: =E41*(1+가정!$B$27)^(-물고기!T20) -> 0.40644211 | K41: =E41*(1+가정!$B$27)^(물고기!T20) -> 2.460375 | M41: =J41/SUMIF($A$18:$A$74,A41,$J$18:$J$74)*H41 -> 6.5432192 | N41: =K41/SUMIF($A$18:$A$74,A41,$K$18:$K$74)*H41 -> 26.509839 | O41: =물고기!E20 -> 30 | P41: =물고기!F20 -> 70 | Q41: =물고기!G20 -> 1600 | R41: =물고기!I20 -> 50 | S41: =물고기!T20 -> 3
A42: 독도 | B42: bollak | C42: =물고기!B32 -> 볼락 | D42: =물고기!C32 -> 찌낚시 | E42: 30 | F42: =E42/SUMIF($A$18:$A$74,A42,$E$18:$E$74) -> 0.3125 | G42: =F42*H42 -> 32.194617 | H42: =물고기!L32 -> 103.02277 | I42: =물고기!O32 -> 희귀 | J42: =E42*(1+가정!$B$27)^(-물고기!T32) -> 22.222222 | K42: =E42*(1+가정!$B$27)^(물고기!T32) -> 40.5 | M42: =J42/SUMIF($A$18:$A$74,A42,$J$18:$J$74)*H42 -> 35.259355 | N42: =K42/SUMIF($A$18:$A$74,A42,$K$18:$K$74)*H42 -> 28.418116 | O42: =물고기!E32 -> 15 | P42: =물고기!F32 -> 30 | Q42: =물고기!G32 -> 120 | R42: =물고기!I32 -> 22.5 | S42: =물고기!T32 -> 1
A43: 독도 | B43: noraemi | C43: =물고기!B33 -> 쥐노래미 | D43: =물고기!C33 -> 찌낚시 | E43: 24 | F43: =E43/SUMIF($A$18:$A$74,A43,$E$18:$E$74) -> 0.25 | G43: =F43*H43 -> 38.0455 | H43: =물고기!L33 -> 152.182 | I43: =물고기!O33 -> 희귀 | J43: =E43*(1+가정!$B$27)^(-물고기!T33) -> 17.777778 | K43: =E43*(1+가정!$B$27)^(물고기!T33) -> 32.4 | M43: =J43/SUMIF($A$18:$A$74,A43,$J$18:$J$74)*H43 -> 41.667208 | N43: =K43/SUMIF($A$18:$A$74,A43,$K$18:$K$74)*H43 -> 33.582677 | O43: =물고기!E33 -> 20 | P43: =물고기!F33 -> 45 | Q43: =물고기!G33 -> 180 | R43: =물고기!I33 -> 32.5 | S43: =물고기!T33 -> 1
...

Sheet 그물
A1: 그물 (자동 낚시)
A2: 그물은 일정 시간마다 지금 낚시터 물고기 1마리를 잡습니다(부캉이 제외). 그물 칸이 차면 멈추고, 게임을 꺼 둔 동안에도 진행됩니다.
A3: 물고기 질은 캐스팅 거리 효과와 같은 식입니다: 가중치 × (1+캐스팅 등급 배율)^(질 × 기준가 등급 번호). 질 0 = 게이지 한가운데, 1 = 가장 멀리 던진 것과 같음. 행운은 미끼 행운 대신 쓰입니다.
A5: 레벨 | B5: 이름 | C5: 구입·강화 비용 (원) | D5: 누적 비용 (원) | E5: 물고기 질 | F5: 행운 | G5: 크기 분포 지수 | H5: 간격 (초) | I5: 칸 수 | J5: 가득 차는 시간 (분) | K5: 1마리 기대가 강 (원) | L5: 1마리 기대가 배낚시 (원) | M5: 1마리 기대가 알래스카 (원) | N5: 분당 수입 강 (원) | O5: 분당 수입 배낚시 (원) | P5: 분당 수입 알래스카 (원) | Q5: 비용 회수 강 (분) | R5: 비용 회수 배낚시 (분) | S5: 비용 회수 알래스카 (분)
A6: 1 | B6: 작은 그물 | C6: 4000 | D6: =SUM($C$6:C6) -> 4000 | E6: -0.5 | F6: 0 | G6: =MAX(0.9,가정!$B$5-F6*가정!$B$6) -> 1.8 | H6: 90 | I6: 4 | J6: =H6*I6/60 -> 6 | K6: =SUMPRODUCT((낚시터!$A$18:$A$74="강")*낚시터!$E$18:$E$74*(1+$F6*낚시터!$S$18:$S$74*가정!$B$7)*(1+가정!$B$27)^($E6*낚시터!$S$18:$S$74)*낚시터!$Q$18:$Q$74*(낚시터!$O$18:$O$74^2+2*낚시터!$O$18:$O$74*(낚시터!$P$18:$P$74-낚시터!$O$18:$O$74)/(1+$G6)+(낚시터!$P$18:$P$74-낚시터!$O$18:$O$74)^2/(1+2*$G6))/낚시터!$R$18:$R$74^2)/SUMPRODUCT((낚시터!$A$18:$A$74="강")*낚시터!$E$18:$E$74*(1+$F6*낚시터!$S$18:$S$74*가정!$B$7)*(1+가정!$B$27)^($E6*낚시터!$S$18:$S$74)) -> 40.124941 | L6: =SUMPRODUCT((낚시터!$A$18:$A$74="배낚시")*낚시터!$E$18:$E$74*(1+$F6*낚시터!$S$18:$S$74*가정!$B$7)*(1+가정!$B$27)^($E6*낚시터!$S$18:$S$74)*낚시터!$Q$18:$Q$74*(낚시터!$O$18:$O$74^2+2*낚시터!$O$18:$O$74*(낚시터!$P$18:$P$74-낚시터!$O$18:$O$74)/(1+$G6)+(낚시터!$P$18:$P$74-낚시터!$O$18:$O$74)^2/(1+2*$G6))/낚시터!$R$18:$R$74^2)/SUMPRODUCT((낚시터!$A$18:$A$74="배낚시")*낚시터!$E$18:$E$74*(1+$F6*낚시터!$S$18:$S$74*가정!$B$7)*(1+가정!$B$27)^($E6*낚시터!$S$18:$S$74)) -> 669.03783 | M6: =SUMPRODUCT((낚시터!$A$18:$A$74="알래스카")*낚시터!$E$18:$E$74*(1+$F6*낚시터!$S$18:$S$74*가정!$B$7)*(1+가정!$B$27)^($E6*낚시터!$S$18:$S$74)*낚시터!$Q$18:$Q$74*(낚시터!$O$18:$O$74^2+2*낚시터!$O$18:$O$74*(낚시터!$P$18:$P$74-낚시터!$O$18:$O$74)/(1+$G6)+(낚시터!$P$18:$P$74-낚시터!$O$18:$O$74)^2/(1+2*$G6))/낚시터!$R$18:$R$74^2)/SUMPRODUCT((낚시터!$A$18:$A$74="알래스카")*낚시터!$E$18:$E$74*(1+$F6*낚시터!$S$18:$S$74*가정!$B$7)*(1+가정!$B$27)^($E6*낚시터!$S$18:$S$74)) -> 1943.4213 | N6: =K6/$H6*60 -> 26.749961 | O6: =L6/$H6*60 -> 446.02522 | P6: =M6/$H6*60 -> 1295.6142 | Q6: =C6/N6 -> 149.53293 | R6: =C6/O6 -> 8.9681028 | S6: =C6/P6 -> 3.0873389
A7: 2 | B7: 자망 | C7: 16000 | D7: =SUM($C$6:C7) -> 20000 | E7: 0 | F7: 0.1 | G7: =MAX(0.9,가정!$B$5-F7*가정!$B$6) -> 1.74 | H7: 75 | I7: 6 | J7: =H7*I7/60 -> 7.5 | K7: =SUMPRODUCT((낚시터!$A$18:$A$74="강")*낚시터!$E$18:$E$74*(1+$F7*낚시터!$S$18:$S$74*가정!$B$7)*(1+가정!$B$27)^($E7*낚시터!$S$18:$S$74)*낚시터!$Q$18:$Q$74*(낚시터!$O$18:$O$74^2+2*낚시터!$O$18:$O$74*(낚시터!$P$18:$P$74-낚시터!$O$18:$O$74)/(1+$G7)+(낚시터!$P$18:$P$74-낚시터!$O$18:$O$74)^2/(1+2*$G7))/낚시터!$R$18:$R$74^2)/SUMPRODUCT((낚시터!$A$18:$A$74="강")*낚시터!$E$18:$E$74*(1+$F7*낚시터!$S$18:$S$74*가정!$B$7)*(1+가정!$B$27)^($E7*낚시터!$S$18:$S$74)) -> 49.518085 | L7: =SUMPRODUCT((낚시터!$A$18:$A$74="배낚시")*낚시터!$E$18:$E$74*(1+$F7*낚시터!$S$18:$S$74*가정!$B$7)*(1+가정!$B$27)^($E7*낚시터!$S$18:$S$74)*낚시터!$Q$18:$Q$74*(낚시터!$O$18:$O$74^2+2*낚시터!$O$18:$O$74*(낚시터!$P$18:$P$74-낚시터!$O$18:$O$74)/(1+$G7)+(낚시터!$P$18:$P$74-낚시터!$O$18:$O$74)^2/(1+2*$G7))/낚시터!$R$18:$R$74^2)/SUMPRODUCT((낚시터!$A$18:$A$74="배낚시")*낚시터!$E$18:$E$74*(1+$F7*낚시터!$S$18:$S$74*가정!$B$7)*(1+가정!$B$27)^($E7*낚시터!$S$18:$S$74)) -> 789.78586 | M7: =SUMPRODUCT((낚시터!$A$18:$A$74="알래스카")*낚시터!$E$18:$E$74*(1+$F7*낚시터!$S$18:$S$74*가정!$B$7)*(1+가정!$B$27)^($E7*낚시터!$S$18:$S$74)*낚시터!$Q$18:$Q$74*(낚시터!$O$18:$O$74^2+2*낚시터!$O$18:$O$74*(낚시터!$P$18:$P$74-낚시터!$O$18:$O$74)/(1+$G7)+(낚시터!$P$18:$P$74-낚시터!$O$18:$O$74)^2/(1+2*$G7))/낚시터!$R$18:$R$74^2)/SUMPRODUCT((낚시터!$A$18:$A$74="알래스카")*낚시터!$E$18:$E$74*(1+$F7*낚시터!$S$18:$S$74*가정!$B$7)*(1+가정!$B$27)^($E7*낚시터!$S$18:$S$74)) -> 2047.6666 | N7: =K7/$H7*60 -> 39.614468 | O7: =L7/$H7*60 -> 631.82869 | P7: =M7/$H7*60 -> 1638.1333 | Q7: =C7/N7 -> 403.89284 | R7: =C7/O7 -> 25.32332 | S7: =C7/P7 -> 9.767215
A8: 3 | B8: 나일론 정치망 | C8: 50000 | D8: =SUM($C$6:C8) -> 70000 | E8: 0.5 | F8: 0.2 | G8: =MAX(0.9,가정!$B$5-F8*가정!$B$6) -> 1.68 | H8: 60 | I8: 8 | J8: =H8*I8/60 -> 8 | K8: =SUMPRODUCT((낚시터!$A$18:$A$74="강")*낚시터!$E$18:$E$74*(1+$F8*낚시터!$S$18:$S$74*가정!$B$7)*(1+가정!$B$27)^($E8*낚시터!$S$18:$S$74)*낚시터!$Q$18:$Q$74*(낚시터!$O$18:$O$74^2+2*낚시터!$O$18:$O$74*(낚시터!$P$18:$P$74-낚시터!$O$18:$O$74)/(1+$G8)+(낚시터!$P$18:$P$74-낚시터!$O$18:$O$74)^2/(1+2*$G8))/낚시터!$R$18:$R$74^2)/SUMPRODUCT((낚시터!$A$18:$A$74="강")*낚시터!$E$18:$E$74*(1+$F8*낚시터!$S$18:$S$74*가정!$B$7)*(1+가정!$B$27)^($E8*낚시터!$S$18:$S$74)) -> 61.940683 | L8: =SUMPRODUCT((낚시터!$A$18:$A$74="배낚시")*낚시터!$E$18:$E$74*(1+$F8*낚시터!$S$18:$S$74*가정!$B$7)*(1+가정!$B$27)^($E8*낚시터!$S$18:$S$74)*낚시터!$Q$18:$Q$74*(낚시터!$O$18:$O$74^2+2*낚시터!$O$18:$O$74*(낚시터!$P$18:$P$74-낚시터!$O$18:$O$74)/(1+$G8)+(낚시터!$P$18:$P$74-낚시터!$O$18:$O$74)^2/(1+2*$G8))/낚시터!$R$18:$R$74^2)/SUMPRODUCT((낚시터!$A$18:$A$74="배낚시")*낚시터!$E$18:$E$74*(1+$F8*낚시터!$S$18:$S$74*가정!$B$7)*(1+가정!$B$27)^($E8*낚시터!$S$18:$S$74)) -> 922.6718 | M8: =SUMPRODUCT((낚시터!$A$18:$A$74="알래스카")*낚시터!$E$18:$E$74*(1+$F8*낚시터!$S$18:$S$74*가정!$B$7)*(1+가정!$B$27)^($E8*낚시터!$S$18:$S$74)*낚시터!$Q$18:$Q$74*(낚시터!$O$18:$O$74^2+2*낚시터!$O$18:$O$74*(낚시터!$P$18:$P$74-낚시터!$O$18:$O$74)/(1+$G8)+(낚시터!$P$18:$P$74-낚시터!$O$18:$O$74)^2/(1+2*$G8))/낚시터!$R$18:$R$74^2)/SUMPRODUCT((낚시터!$A$18:$A$74="알래스카")*낚시터!$E$18:$E$74*(1+$F8*낚시터!$S$18:$S$74*가정!$B$7)*(1+가정!$B$27)^($E8*낚시터!$S$18:$S$74)) -> 2161.7058 | N8: =K8/$H8*60 -> 61.940683 | O8: =L8/$H8*60 -> 922.6718 | P8: =M8/$H8*60 -> 2161.7058 | Q8: =C8/N8 -> 807.22391 | R8: =C8/O8 -> 54.19045 | S8: =C8/P8 -> 23.129882
A9: 4 | B9: 대형 정치망 | C9: 125000 | D9: =SUM($C$6:C9) -> 195000 | E9: 1 | F9: 0.35 | G9: =MAX(0.9,가정!$B$5-F9*가정!$B$6) -> 1.59 | H9: 45 | I9: 10 | J9: =H9*I9/60 -> 7.5 | K9: =SUMPRODUCT((낚시터!$A$18:$A$74="강")*낚시터!$E$18:$E$74*(1+$F9*낚시터!$S$18:$S$74*가정!$B$7)*(1+가정!$B$27)^($E9*낚시터!$S$18:$S$74)*낚시터!$Q$18:$Q$74*(낚시터!$O$18:$O$74^2+2*낚시터!$O$18:$O$74*(낚시터!$P$18:$P$74-낚시터!$O$18:$O$74)/(1+$G9)+(낚시터!$P$18:$P$74-낚시터!$O$18:$O$74)^2/(1+2*$G9))/낚시터!$R$18:$R$74^2)/SUMPRODUCT((낚시터!$A$18:$A$74="강")*낚시터!$E$18:$E$74*(1+$F9*낚시터!$S$18:$S$74*가정!$B$7)*(1+가정!$B$27)^($E9*낚시터!$S$18:$S$74)) -> 80.42701 | L9: =SUMPRODUCT((낚시터!$A$18:$A$74="배낚시")*낚시터!$E$18:$E$74*(1+$F9*낚시터!$S$18:$S$74*가정!$B$7)*(1+가정!$B$27)^($E9*낚시터!$S$18:$S$74)*낚시터!$Q$18:$Q$74*(낚시터!$O$18:$O$74^2+2*낚시터!$O$18:$O$74*(낚시터!$P$18:$P$74-낚시터!$O$18:$O$74)/(1+$G9)+(낚시터!$P$18:$P$74-낚시터!$O$18:$O$74)^2/(1+2*$G9))/낚시터!$R$18:$R$74^2)/SUMPRODUCT((낚시터!$A$18:$A$74="배낚시")*낚시터!$E$18:$E$74*(1+$F9*낚시터!$S$18:$S$74*가정!$B$7)*(1+가정!$B$27)^($E9*낚시터!$S$18:$S$74)) -> 1083.7861 | M9: =SUMPRODUCT((낚시터!$A$18:$A$74="알래스카")*낚시터!$E$18:$E$74*(1+$F9*낚시터!$S$18:$S$74*가정!$B$7)*(1+가정!$B$27)^($E9*낚시터!$S$18:$S$74)*낚시터!$Q$18:$Q$74*(낚시터!$O$18:$O$74^2+2*낚시터!$O$18:$O$74*(낚시터!$P$18:$P$74-낚시터!$O$18:$O$74)/(1+$G9)+(낚시터!$P$18:$P$74-낚시터!$O$18:$O$74)^2/(1+2*$G9))/낚시터!$R$18:$R$74^2)/SUMPRODUCT((낚시터!$A$18:$A$74="알래스카")*낚시터!$E$18:$E$74*(1+$F9*낚시터!$S$18:$S$74*가정!$B$7)*(1+가정!$B$27)^($E9*낚시터!$S$18:$S$74)) -> 2306.9076 | N9: =K9/$H9*60 -> 107.23601 | O9: =L9/$H9*60 -> 1445.0481 | P9: =M9/$H9*60 -> 3075.8768 | Q9: =C9/N9 -> 1165.6532 | R9: =C9/O9 -> 86.502312 | S9: =C9/P9 -> 40.638819
A10: 5 | B10: 황금 그물 | C10: 340000 | D10: =SUM($C$6:C10) -> 535000 | E10: 1.6 | F10: 0.5 | G10: =MAX(0.9,가정!$B$5-F10*가정!$B$6) -> 1.5 | H10: 30 | I10: 12 | J10: =H10*I10/60 -> 6 | K10: =SUMPRODUCT((낚시터!$A$18:$A$74="강")*낚시터!$E$18:$E$74*(1+$F10*낚시터!$S$18:$S$74*가정!$B$7)*(1+가정!$B$27)^($E10*낚시터!$S$18:$S$74)*낚시터!$Q$18:$Q$74*(낚시터!$O$18:$O$74^2+2*낚시터!$O$18:$O$74*(낚시터!$P$18:$P$74-낚시터!$O$18:$O$74)/(1+$G10)+(낚시터!$P$18:$P$74-낚시터!$O$18:$O$74)^2/(1+2*$G10))/낚시터!$R$18:$R$74^2)/SUMPRODUCT((낚시터!$A$18:$A$74="강")*낚시터!$E$18:$E$74*(1+$F10*낚시터!$S$18:$S$74*가정!$B$7)*(1+가정!$B$27)^($E10*낚시터!$S$18:$S$74)) -> 109.70862 | L10: =SUMPRODUCT((낚시터!$A$18:$A$74="배낚시")*낚시터!$E$18:$E$74*(1+$F10*낚시터!$S$18:$S$74*가정!$B$7)*(1+가정!$B$27)^($E10*낚시터!$S$18:$S$74)*낚시터!$Q$18:$Q$74*(낚시터!$O$18:$O$74^2+2*낚시터!$O$18:$O$74*(낚시터!$P$18:$P$74-낚시터!$O$18:$O$74)/(1+$G10)+(낚시터!$P$18:$P$74-낚시터!$O$18:$O$74)^2/(1+2*$G10))/낚시터!$R$18:$R$74^2)/SUMPRODUCT((낚시터!$A$18:$A$74="배낚시")*낚시터!$E$18:$E$74*(1+$F10*낚시터!$S$18:$S$74*가정!$B$7)*(1+가정!$B$27)^($E10*낚시터!$S$18:$S$74)) -> 1284.1635 | M10: =SUMPRODUCT((낚시터!$A$18:$A$74="알래스카")*낚시터!$E$18:$E$74*(1+$F10*낚시터!$S$18:$S$74*가정!$B$7)*(1+가정!$B$27)^($E10*낚시터!$S$18:$S$74)*낚시터!$Q$18:$Q$74*(낚시터!$O$18:$O$74^2+2*낚시터!$O$18:$O$74*(낚시터!$P$18:$P$74-낚시터!$O$18:$O$74)/(1+$G10)+(낚시터!$P$18:$P$74-낚시터!$O$18:$O$74)^2/(1+2*$G10))/낚시터!$R$18:$R$74^2)/SUMPRODUCT((낚시터!$A$18:$A$74="알래스카")*낚시터!$E$18:$E$74*(1+$F10*낚시터!$S$18:$S$74*가정!$B$7)*(1+가정!$B$27)^($E10*낚시터!$S$18:$S$74)) -> 2485.4365 | N10: =K10/$H10*60 -> 219.41724 | O10: =L10/$H10*60 -> 2568.327 | P10: =M10/$H10*60 -> 4970.8729 | Q10: =C10/N10 -> 1549.5592 | R10: =C10/O10 -> 132.3819 | S10: =C10/P10 -> 68.398449

Sheet 보스
A1: 맵별 보스 대물
A2: 그 맵에서 직접 잡은 물고기가 기척 수에 차면 다음 입질이 보스입니다. 거리에 따라 3단계로 나뉘고, 2단계부터 경고 뒤 잠수(강한 당김)가 옵니다.
A3: 보스 크기는 t = 난수^지수로 정해집니다(일반 물고기보다 큰 개체가 잘 나옴). 놓치면 기척이 일부 남습니다.
A4: 보스 크기 분포 지수 | B4: 1.2 | C4: 놓쳤을 때 남는 기척 비율 | D4: 0.6 | E4: 감기 속도 배수 | F4: 0.7
A6: 낚시터 | B6: 보스 | C6: 모습(기준 종) | D6: 최소 길이 (cm) | E6: 최대 길이 (cm) | F6: 기준가 (원) | G6: 기척 (마리) | H6: 난이도 (0~1) | I6: 평균 길이 (cm) | J6: 보스 기대 판매가 (원) | K6: 기척 채우는 동안 기대 수입 (원) | L6: 보스 가치 배수 | M6: 단계별 추가 당김 (2·3단계) | N6: 잠수 당김
A7: =낚시터!B6 -> 하천 | B7: 여울 대장 꺽지 | C7: 꺽지 | D7: 45 | E7: 60 | F7: 1500 | G7: 30 | H7: 0.74 | I7: =(D7+E7)/2 -> 52.5 | J7: =F7*(D7^2+2*D7*(E7-D7)/(1+$B$4)+(E7-D7)^2/(1+2*$B$4))/I7^2 -> 1472.007 | K7: =G7*낚시터!F6 -> 687.18004 | L7: =J7/K7 -> 2.142098 | M7: =0.08*H7^2*1.5 -> 0.065712 | N7: =0.28*H7^2*1.5 -> 0.229992
A8: =낚시터!B7 -> 강 | B8: 왕메기 | C8: 메기 | D8: 180 | E8: 240 | F8: 4000 | G8: 30 | H8: 0.8 | I8: =(D8+E8)/2 -> 210 | J8: =F8*(D8^2+2*D8*(E8-D8)/(1+$B$4)+(E8-D8)^2/(1+2*$B$4))/I8^2 -> 3925.352 | K8: =G8*낚시터!F7 -> 1410.446 | L8: =J8/K8 -> 2.7830572 | M8: =0.08*H8^2*1.5 -> 0.0768 | N8: =0.28*H8^2*1.5 -> 0.2688
A9: =낚시터!B8 -> 방파제 | B9: 방파제 돌돔왕 | C9: 돌돔 | D9: 90 | E9: 120 | F9: 9000 | G9: 30 | H9: 0.86 | I9: =(D9+E9)/2 -> 105 | J9: =F9*(D9^2+2*D9*(E9-D9)/(1+$B$4)+(E9-D9)^2/(1+2*$B$4))/I9^2 -> 8832.0419 | K9: =G9*낚시터!F8 -> 3666.6461 | L9: =J9/K9 -> 2.4087522 | M9: =0.08*H9^2*1.5 -> 0.088752 | N9: =0.28*H9^2*1.5 -> 0.310632
A10: =낚시터!B9 -> 독도 | B10: 독도 혹돔왕 | C10: 혹돔 | D10: 120 | E10: 160 | F10: 20000 | G10: 30 | H10: 0.9 | I10: =(D10+E10)/2 -> 140 | J10: =F10*(D10^2+2*D10*(E10-D10)/(1+$B$4)+(E10-D10)^2/(1+2*$B$4))/I10^2 -> 19626.76 | K10: =G10*낚시터!F9 -> 8082.8756 | L10: =J10/K10 -> 2.4281902 | M10: =0.08*H10^2*1.5 -> 0.0972 | N10: =0.28*H10^2*1.5 -> 0.3402
A11: =낚시터!B10 -> 배낚시 | B11: 바다의 폭군 참다랑어 | C11: 참다랑어 | D11: 300 | E11: 380 | F11: 60000 | G11: 30 | H11: 0.94 | I11: =(D11+E11)/2 -> 340 | J11: =F11*(D11^2+2*D11*(E11-D11)/(1+$B$4)+(E11-D11)^2/(1+2*$B$4))/I11^2 -> 59014.118 | K11: =G11*낚시터!F10 -> 22748.078 | L11: =J11/K11 -> 2.5942463 | M11: =0.08*H11^2*1.5 -> 0.106032 | N11: =0.28*H11^2*1.5 -> 0.371112
A12: =낚시터!B11 -> 아마존 | B12: 괴물 피라루쿠 | C12: 피라루쿠 | D12: 350 | E12: 450 | F12: 100000 | G12: 30 | H12: 0.98 | I12: =(D12+E12)/2 -> 400 | J12: =F12*(D12^2+2*D12*(E12-D12)/(1+$B$4)+(E12-D12)^2/(1+2*$B$4))/I12^2 -> 98287.099 | K12: =G12*낚시터!F11 -> 37854.908 | L12: =J12/K12 -> 2.5964163 | M12: =0.08*H12^2*1.5 -> 0.115248 | N12: =0.28*H12^2*1.5 -> 0.403368
A13: =낚시터!B12 -> 알래스카 | B13: 전설의 핼리벗 | C13: 핼리벗 | D13: 300 | E13: 380 | F13: 160000 | G13: 30 | H13: 1 | I13: =(D13+E13)/2 -> 340 | J13: =F13*(D13^2+2*D13*(E13-D13)/(1+$B$4)+(E13-D13)^2/(1+2*$B$4))/I13^2 -> 157370.98 | K13: =G13*낚시터!F12 -> 60265.111 | L13: =J13/K13 -> 2.6113116 | M13: =0.08*H13^2*1.5 -> 0.12 | N13: =0.28*H13^2*1.5 -> 0.42

Sheet 메달
A1: 크기 메달
A2: 몸길이 범위의 몇 % 지점 이상이면 메달입니다. 처음 받는 단계마다 그 종 기준가 × 보상 배수를 받습니다(동→금을 한 번에 넘으면 셋 다). 예전 2·5·15배에서 0.2·0.5·1배로 낮춤.
A4: 메달 | B4: 범위 대비 지점 | C4: 보상 배수 (× 기준가) | D4: 나올 확률 (떡밥) | E4: 나올 확률 (미끼 행운 1.3)
A5: 동메달 | B5: 0.7 | C5: 0.2 | D5: =1-B5^(1/가정!$B$5) -> 0.17975545 | E5: =1-B5^(1/MAX(0.9,가정!$B$5-1.3*가정!$B$6)) -> 0.2950873
A6: 은메달 | B6: 0.85 | C6: 0.5 | D6: =1-B6^(1/가정!$B$5) -> 0.086332258 | E6: =1-B6^(1/MAX(0.9,가정!$B$5-1.3*가정!$B$6)) -> 0.14728703
A7: 금메달 | B7: 0.95 | C7: 1 | D7: =1-B7^(1/가정!$B$5) -> 0.028094085 | E7: =1-B7^(1/MAX(0.9,가정!$B$5-1.3*가정!$B$6)) -> 0.049044056
A9: 물고기 | B9: 최소 길이 | C9: 최대 길이 | D9: 기준가 (원) | E9: 동메달 (cm~) | F9: 은메달 (cm~) | G9: 금메달 (cm~) | H9: 세 메달 보상 합 (원)
A10: =물고기!B5 -> 붕어 | B10: =물고기!E5 -> 12 | C10: =물고기!F5 -> 30 | D10: =물고기!G5 -> 12 | E10: =ROUND(B10+(C10-B10)*$B$5,1) -> 24.6 | F10: =ROUND(B10+(C10-B10)*$B$6,1) -> 27.3 | G10: =ROUND(B10+(C10-B10)*$B$7,1) -> 29.1 | H10: =D10*SUM($C$5:$C$7) -> 20.4
A11: =물고기!B6 -> 향어 | B11: =물고기!E6 -> 25 | C11: =물고기!F6 -> 50 | D11: =물고기!G6 -> 30 | E11: =ROUND(B11+(C11-B11)*$B$5,1) -> 42.5 | F11: =ROUND(B11+(C11-B11)*$B$6,1) -> 46.3 | G11: =ROUND(B11+(C11-B11)*$B$7,1) -> 48.8 | H11: =D11*SUM($C$5:$C$7) -> 51
A12: =물고기!B7 -> 잉어 | B12: =물고기!E7 -> 30 | C12: =물고기!F7 -> 80 | D12: =물고기!G7 -> 60 | E12: =ROUND(B12+(C12-B12)*$B$5,1) -> 65 | F12: =ROUND(B12+(C12-B12)*$B$6,1) -> 72.5 | G12: =ROUND(B12+(C12-B12)*$B$7,1) -> 77.5 | H12: =D12*SUM($C$5:$C$7) -> 102
A13: =물고기!B8 -> 피라미 | B13: =물고기!E8 -> 6 | C13: =물고기!F8 -> 15 | D13: =물고기!G8 -> 6 | E13: =ROUND(B13+(C13-B13)*$B$5,1) -> 12.3 | F13: =ROUND(B13+(C13-B13)*$B$6,1) -> 13.7 | G13: =ROUND(B13+(C13-B13)*$B$7,1) -> 14.6 | H13: =D13*SUM($C$5:$C$7) -> 10.2
A14: =물고기!B9 -> 메기 | B14: =물고기!E9 -> 30 | C14: =물고기!F9 -> 90 | D14: =물고기!G9 -> 70 | E14: =ROUND(B14+(C14-B14)*$B$5,1) -> 72 | F14: =ROUND(B14+(C14-B14)*$B$6,1) -> 81 | G14: =ROUND(B14+(C14-B14)*$B$7,1) -> 87 | H14: =D14*SUM($C$5:$C$7) -> 119
A15: =물고기!B10 -> 쏘가리 | B15: =물고기!E10 -> 20 | C15: =물고기!F10 -> 55 | D15: =물고기!G10 -> 160 | E15: =ROUND(B15+(C15-B15)*$B$5,1) -> 44.5 | F15: =ROUND(B15+(C15-B15)*$B$6,1) -> 49.8 | G15: =ROUND(B15+(C15-B15)*$B$7,1) -> 53.3 | H15: =D15*SUM($C$5:$C$7) -> 272
A16: =물고기!B11 -> 민물장어 | B16: =물고기!E11 -> 40 | C16: =물고기!F11 -> 100 | D16: =물고기!G11 -> 400 | E16: =ROUND(B16+(C16-B16)*$B$5,1) -> 82 | F16: =ROUND(B16+(C16-B16)*$B$6,1) -> 91 | G16: =ROUND(B16+(C16-B16)*$B$7,1) -> 97 | H16: =D16*SUM($C$5:$C$7) -> 680
A17: =물고기!B12 -> 철갑상어 | B17: =물고기!E12 -> 80 | C17: =물고기!F12 -> 200 | D17: =물고기!G12 -> 1800 | E17: =ROUND(B17+(C17-B17)*$B$5,1) -> 164 | F17: =ROUND(B17+(C17-B17)*$B$6,1) -> 182 | G17: =ROUND(B17+(C17-B17)*$B$7,1) -> 194 | H17: =D17*SUM($C$5:$C$7) -> 3060
A18: =물고기!B13 -> 망둥어 | B18: =물고기!E13 -> 8 | C18: =물고기!F13 -> 25 | D18: =물고기!G13 -> 15 | E18: =ROUND(B18+(C18-B18)*$B$5,1) -> 19.9 | F18: =ROUND(B18+(C18-B18)*$B$6,1) -> 22.5 | G18: =ROUND(B18+(C18-B18)*$B$7,1) -> 24.2 | H18: =D18*SUM($C$5:$C$7) -> 25.5
A19: =물고기!B14 -> 전갱이 | B19: =물고기!E14 -> 15 | C19: =물고기!F14 -> 40 | D19: =물고기!G14 -> 35 | E19: =ROUND(B19+(C19-B19)*$B$5,1) -> 32.5 | F19: =ROUND(B19+(C19-B19)*$B$6,1) -> 36.3 | G19: =ROUND(B19+(C19-B19)*$B$7,1) -> 38.8 | H19: =D19*SUM($C$5:$C$7) -> 59.5
A20: =물고기!B15 -> 고등어 | B20: =물고기!E15 -> 25 | C20: =물고기!F15 -> 50 | D20: =물고기!G15 -> 60 | E20: =ROUND(B20+(C20-B20)*$B$5,1) -> 42.5 | F20: =ROUND(B20+(C20-B20)*$B$6,1) -> 46.3 | G20: =ROUND(B20+(C20-B20)*$B$7,1) -> 48.8 | H20: =D20*SUM($C$5:$C$7) -> 102
A21: =물고기!B16 -> 우럭 | B21: =물고기!E16 -> 20 | C21: =물고기!F16 -> 50 | D21: =물고기!G16 -> 150 | E21: =ROUND(B21+(C21-B21)*$B$5,1) -> 41 | F21: =ROUND(B21+(C21-B21)*$B$6,1) -> 45.5 | G21: =ROUND(B21+(C21-B21)*$B$7,1) -> 48.5 | H21: =D21*SUM($C$5:$C$7) -> 255
... A56: =물고기!B51 -> 오륙도 돗돔 | B56: =물고기!E51 -> 100 | C56: =물고기!F51 -> 220 | D56: =물고기!G51 -> 20000 | E56: =ROUND(B56+(C56-B56)*$B$5,1) -> 184 | F56: =ROUND(B56+(C56-B56)*$B$6,1) -> 202 | G56: =ROUND(B56+(C56-B56)*$B$7,1) -> 214 | H56: =D56*SUM($C$5:$C$7) -> 34000
G57: 전 종 금메달 보상 합 | H57: =SUM(H10:H56) -> 180953.1

Sheet 시간·날씨
A1: 시간대와 날씨
A2: 실제 시각으로 진행합니다. 같은 시각이면 누구에게나 같은 날씨입니다. 실내 낚시터는 영향이 없고, 부산은 늘 밤입니다.
A4: 항목 | B4: 값 | C4: 설명
A5: 하루 길이 (분) | B5: 12 | C5: 새벽 15% · 낮 40% · 저녁 15% · 밤 30%
A6: 날씨 바뀌는 간격 (분) | B6: 3
A7: 맑음 확률 | B7: 0.6
A8: 비 확률 | B8: 0.25 | C8: 알래스카는 눈보라
A9: 안개 확률 | B9: 0.15
A10: 밤: 야행성 물고기 출현 배수 | B10: 1.3 | C10: 갈치·장어·메기·볼락·쥐노래미·레드테일 캣피시·링코드·해운대 은갈치
A11: 밤: 야행성 물고기 가격 배수 | B11: 1.5
A12: 밤: 좋은 물고기 보정 | B12: 0.3 | C12: 캐스팅 거리 보정과 같은 식
A13: 비·눈보라: 좋은 물고기 보정 | B13: 0.25
A14: 비·눈보라: 입질 대기 배수 | B14: 0.8
A15: 안개: 부캉이 확률 배수 | B15: 2
A16: 안개: 희귀 변종 확률 배수 | B16: 2
A18: 맵별 1마리 평균 판매가 (게임 안에서 2만 번 굴린 측정값, 변종·부캉이 제외)
A19: 낚시터 | B19: 낮·맑음 | C19: 밤·맑음 | D19: 낮·비 | E19: 낮·안개 | F19: 밤 / 낮 | G19: 비 / 맑음
A20: =낚시터!B6 -> 하천 | B20: 28 | C20: 30 | D20: 30 | E20: 30 | F20: =C20/B20 -> 1.0714286 | G20: =D20/B20 -> 1.0714286
A21: =낚시터!B7 -> 강 | B21: 60 | C21: 84 | D21: 66 | E21: 63 | F21: =C21/B21 -> 1.4 | G21: =D21/B21 -> 1.1
A22: =낚시터!B8 -> 방파제 | B22: 122 | C22: 132 | D22: 130 | E22: 126 | F22: =C22/B22 -> 1.0819672 | G22: =D22/B22 -> 1.0655738
A23: =낚시터!B9 -> 독도 | B23: 319 | C23: 345 | D23: 327 | E23: 322 | F23: =C23/B23 -> 1.0815047 | G23: =D23/B23 -> 1.0250784
A24: =낚시터!B10 -> 배낚시 | B24: 787 | C24: 812 | D24: 845 | E24: 819 | F24: =C24/B24 -> 1.0317662 | G24: =D24/B24 -> 1.0736976
A25: =낚시터!B11 -> 아마존 | B25: 1547 | C25: 1851 | D25: 1553 | E25: 1556 | F25: =C25/B25 -> 1.1965094 | G25: =D25/B25 -> 1.0038785
A26: =낚시터!B12 -> 알래스카 | B26: 2193 | C26: 2574 | D26: 2257 | E26: 2281 | F26: =C26/B26 -> 1.1737346 | G26: =D26/B26 -> 1.0291838
A27: =낚시터!B13 -> 부산 | B27: 1911 | C27: 2162 | D27: 1975 | E27: 1995 | F27: =C27/B27 -> 1.1313448 | G27: =D27/B27 -> 1.0334903
A29: 날씨 이벤트 (날씨 구간마다, 낚시터마다 정해짐)
A30: 구간마다 이벤트가 생길 확률 | B30: 0.5
A31: 이벤트 | B31: 생기는 날씨 | C31: 출현 배수 | D31: 난이도 + | E31: 판매가 배수 | F31: 입질 대기 배수 | G31: 좋은 물고기 보정 | H31: 설명
A32: 물고기 떼 | B32: 맑음, 비, 안개, 눈보라 | C32: 3 | D32: 0 | E32: 1 | F32: 1 | G32: 0 | H32: 떼가 몰려왔어요 · 그 물고기 출현 3배
A33: 거센 물살 | B33: 비, 눈보라 | C33: 1 | D33: 0.15 | E33: 1.2 | F33: 1 | G33: 0 | H33: 물고기 힘이 세져 잡기 어렵지만 판매가 ×1.2
A34: 먹이 활동 | B34: 맑음 | C34: 1 | D34: 0 | E34: 1 | F34: 0.65 | G34: 0 | H34: 입질이 훨씬 빨라져요
A35: 안개 속 대물 | B35: 안개 | C35: 1 | D35: 0 | E35: 1 | F35: 1.25 | G35: 0.5 | H35: 좋은 물고기가 늘지만 입질이 느려요
A36: 맑을 때 이벤트별 확률 (물고기 떼·먹이 활동) | B36: =B30/2 -> 0.25
A37: 비·눈보라일 때 거센 물살 확률 | B37: =B30/2 -> 0.25
A38: 안개일 때 안개 속 대물 확률 | B38: =B30/2 -> 0.25

Sheet 콘텐츠
A1: 수족관 · 특수 미끼 · 낚시 대회 · 환생 · 의뢰 · 희귀 변종
A3: 수족관
A4: 시간당 관람 수입 (전시 물고기 가격 합 대비) | B4: 0.1
A5: 꺼 둔 동안 최대 (시간) | B5: 24
A6: 예시: 전시 물고기 1마리 평균 가격 (원) | B6: 2000
A8: 수조 | B8: 비용 (원) | C8: 누적 비용 (원) | D8: 전시 칸 | E8: 가득 채웠을 때 시간당 수입 (원) | F8: 하루 최대 (원) | G8: 누적 비용 회수 (시간)
A9: 작은 어항 | B9: 20000 | C9: =SUM($B$9:B9) -> 20000 | D9: 3 | E9: =D9*$B$6*$B$4 -> 600 | F9: =E9*$B$5 -> 14400 | G9: =C9/E9 -> 33.333333
A10: 거실 수조 | B10: 60000 | C10: =SUM($B$9:B10) -> 80000 | D10: 5 | E10: =D10*$B$6*$B$4 -> 1000 | F10: =E10*$B$5 -> 24000 | G10: =C10/E10 -> 80
A11: 대형 수조 | B11: 150000 | C11: =SUM($B$9:B11) -> 230000 | D11: 8 | E11: =D11*$B$6*$B$4 -> 1600 | F11: =E11*$B$5 -> 38400 | G11: =C11/E11 -> 143.75
A12: 해양 수족관 | B12: 400000 | C12: =SUM($B$9:B12) -> 630000 | D12: 12 | E12: =D12*$B$6*$B$4 -> 2400 | F12: =E12*$B$5 -> 57600 | G12: =C12/E12 -> 262.5
A13: 부캉이 아쿠아리움 | B13: 1000000 | C13: =SUM($B$9:B13) -> 1630000 | D13: 16 | E13: =D13*$B$6*$B$4 -> 3200 | F13: =E13*$B$5 -> 76800 | G13: =C13/E13 -> 509.375
A15: 특수 미끼
A16: 미끼 | B16: 가격 (원) | C16: 횟수 | D16: 1회당 (원) | E16: 효과
A17: 대물 미끼 | B17: 3000 | C17: 10 | D17: =B17/C17 -> 300 | E17: 좋은 물고기가 더 잘 와요 (멀리 던진 것보다 더)
A18: 부캉이 미끼 | B18: 8000 | C18: 10 | D18: =B18/C18 -> 800 | E18: 부캉이가 나올 확률 5배
A19: 보스 유인 미끼 | B19: 15000 | C19: 1 | D19: =B19/C19 -> 15000 | E19: 지금 낚시터 보스 기척 +10
A21: 낚시 대회
A22: 시간 (초) | B22: 180
A23: 참가비 = 1마리 기대가 × | B23: 10
A24: 상금 배수 (1위·2위·3위·4위) | B24: 6 | C24: 3 | D24: 1.5 | E24: 0
A26: 낚시터 | B26: 참가비 (원) | C26: 1위 상금 | D26: 2위 상금 | E26: 3위 상금 | F26: 라이벌
A27: =낚시터!B6 -> 하천 | B27: =MAX(100,ROUND(낚시터!F6*$B$23/10,0)*10) -> 230 | C27: =B27*B$24 -> 1380 | D27: =B27*C$24 -> 690 | E27: =B27*D$24 -> 345 | F27: 낚시왕 박(1.25) · 강태공 김(1) · 초보 이(0.7)
A28: =낚시터!B7 -> 강 | B28: =MAX(100,ROUND(낚시터!F7*$B$23/10,0)*10) -> 470 | C28: =B28*B$24 -> 2820 | D28: =B28*C$24 -> 1410 | E28: =B28*D$24 -> 705 | F28: 낚시왕 박(1.25) · 강태공 김(1) · 초보 이(0.7)
A29: =낚시터!B8 -> 방파제 | B29: =MAX(100,ROUND(낚시터!F8*$B$23/10,0)*10) -> 1220 | C29: =B29*B$24 -> 7320 | D29: =B29*C$24 -> 3660 | E29: =B29*D$24 -> 1830 | F29: 낚시왕 박(1.25) · 강태공 김(1) · 초보 이(0.7)
A30: =낚시터!B9 -> 독도 | B30: =MAX(100,ROUND(낚시터!F9*$B$23/10,0)*10) -> 2690 | C30: =B30*B$24 -> 16140 | D30: =B30*C$24 -> 8070 | E30: =B30*D$24 -> 4035 | F30: 낚시왕 박(1.25) · 강태공 김(1) · 초보 이(0.7)
A31: =낚시터!B10 -> 배낚시 | B31: =MAX(100,ROUND(낚시터!F10*$B$23/10,0)*10) -> 7580 | C31: =B31*B$24 -> 45480 | D31: =B31*C$24 -> 22740 | E31: =B31*D$24 -> 11370 | F31: 낚시왕 박(1.25) · 강태공 김(1) · 초보 이(0.7)
A32: =낚시터!B11 -> 아마존 | B32: =MAX(100,ROUND(낚시터!F11*$B$23/10,0)*10) -> 12620 | C32: =B32*B$24 -> 75720 | D32: =B32*C$24 -> 37860 | E32: =B32*D$24 -> 18930 | F32: 낚시왕 박(1.25) · 강태공 김(1) · 초보 이(0.7)
A33: =낚시터!B12 -> 알래스카 | B33: =MAX(100,ROUND(낚시터!F12*$B$23/10,0)*10) -> 20090 | C33: =B33*B$24 -> 120540 | D33: =B33*C$24 -> 60270 | E33: =B33*D$24 -> 30135 | F33: 낚시왕 박(1.25) · 강태공 김(1) · 초보 이(0.7)
A35: 환생
A36: 레벨당 판매가 보너스 | B36: 0.1
A37: 레벨당 보스 기척 보너스 | B37: 0.1
A38: 환생 후 시작 금액 (원) | B38: 150
A39: 환생 레벨 | B39: 판매가 배수 | C39: 보스 기척 1마리당
A40: 1 | B40: =1+A40*$B$36 -> 1.1 | C40: =1+A40*$B$37 -> 1.1
A41: 2 | B41: =1+A41*$B$36 -> 1.2 | C41: =1+A41*$B$37 -> 1.2
A42: 3 | B42: =1+A42*$B$36 -> 1.3 | C42: =1+A42*$B$37 -> 1.3
A43: 4 | B43: =1+A43*$B$36 -> 1.4 | C43: =1+A43*$B$37 -> 1.4
A44: 5 | B44: =1+A44*$B$36 -> 1.5 | C44: =1+A44*$B$37 -> 1.5
A46: 오늘의 의뢰 (하루 3개, 연 낚시터 중 가장 먼 2곳 기준. 새 낚시터를 열면 못 끝낸 의뢰가 바뀜)
A47: 보상 배수 최소·최대 | B47: 4 | C47: 7
...

Sheet 도감 보상
A1: 도감 완성 보상
A2: 낚시터의 물고기를 모두 한 번 이상 잡으면 받는 작은 편의 효과입니다. 부산은 나오는 7종(전용 4종 + 참돔·방어·부시리) 기준입니다.
A4: 낚시터 | B4: 채워야 할 종 수 | C4: 보상 | D4: 효과 종류 | E4: 수치 | F4: 게임에서 쓰이는 곳
